Workbook

Sheet Bets
A1: BET DESC | C1: 225+ D | D1: DATE | E1: SPORT | F1: EVENT | G1: BUY-IN | P1: WIN | R1: TOTAL BUY-IN | S1: TOTAL PAYOUT | T1: ODDS | V1: BET PROPS | Z1: PAYOUT
A2: GTD | G2: WOLF | H2: FELIPE | I2: CHOI | J2: JO | K2: TRIGO | L2: HU | M2: BUENO | N2: NINHO | V2: NOW | W2: / | X2: PROP | Z2: WOLF | AA2: CHOI | AB2: FELIPE | AC2: JO | AD2: TRIGO | AE2: HU | AF2: BUENO | AG2: NINHO
A3: FALSE | D3: 45174 | E3: NFL | F3: 🏈 23-24 Futures | G3: 1 | H3: 1 | P3: FALSE | R3: =IF(G3 <> "",SUM(G3:O3),) -> 2 | S3: 22 | T3: =IFERROR(IF((S3-R3)>R444,"+"&ROUND(((S3-R3)/R3)*100,0),"-"&ROUND((S3/(R3-S3))*100, 0)),) -> +1000 | V3: =IF(ISBLANK($D3), "0",) | W3: =IF(ISBLANK($D3), "/",) | Z3: =IF(G3<>"", IF(AND($P3=FALSE, $A3=FALSE), -G3, IF(AND($P3=FALSE, $A3=TRUE), 0, IF($P3=TRUE, (G3 / $R3) * 100 * ($S3 / 100)-G3, ))), ) -> -1 | AA3: =IF(I3<>"", IF(AND($P3=FALSE, $A3=FALSE), -I3, IF(AND($P3=FALSE, $A3=TRUE), 0, IF($P3=TRUE, (I3 / $R3) * 100 * ($S3 / 100)-I3, ))), ) | AB3: =IF(H3<>"", IF(AND($P3=FALSE, $A3=FALSE), -H3, IF(AND($P3=FALSE, $A3=TRUE), 0, IF($P3=TRUE, (H3 / $R3) * 100 * ($S3 / 100)-H3, ))), ) -> -1 | AC3: =IF(J3<>"", IF(AND($P3=FALSE, $A3=FALSE), -J3, IF(AND($P3=FALSE, $A3=TRUE), 0, IF($P3=TRUE, (J3 / $R3) * 100 * ($S3 / 100)-J3, ))), ) | AD3: =IF(K3<>"", IF(AND($P3=FALSE, $A3=FALSE), -K3, IF(AND($P3=FALSE, $A3=TRUE), 0, IF($P3=TRUE, (K3 / $R3) * 100 * ($S3 / 100)-K3, ))), ) | AE3: =IF(L3<>"", IF(AND($P3=FALSE, $A3=FALSE), -L3, IF(AND($P3=FALSE, $A3=TRUE), 0, IF($P3=TRUE, (L3 / $R3) * 100 * ($S3 / 100)-L3, ))), ) | AF3: =IF(M3<>"", IF(AND($P3=FALSE, $A3=FALSE), -M3, IF(AND($P3=FALSE, $A3=TRUE), 0, IF($P3=TRUE, (M3 / $R3) * 100 * ($S3 / 100)-M3, ))), ) | AG3: =IF(N3<>"", IF(AND($P3=FALSE, $A3=FALSE), -N3, IF(AND($P3=FALSE, $A3=TRUE), 0, IF($P3=TRUE, (N3 / $R3) * 100 * ($S3 / 100)-N3, ))), )
A4: FALSE | P4: FALSE | R4: =IF(G4 <> "",SUM(G4:O4),) | V4: =IF(ISBLANK($D4), "0",) -> 0 | W4: =IF(ISBLANK($D4), "/",) -> / | X4: SB LVIII - SF 49ers | Z4: =IF(G4<>"", IF(AND($P4=FALSE, $A4=FALSE), -G4, IF(AND($P4=FALSE, $A4=TRUE), 0, IF($P4=TRUE, (G4 / $R4) * 100 * ($S4 / 100)-G4, ))), ) | AA4: =IF(I4<>"", IF(AND($P4=FALSE, $A4=FALSE), -I4, IF(AND($P4=FALSE, $A4=TRUE), 0, IF($P4=TRUE, (I4 / $R4) * 100 * ($S4 / 100)-I4, ))), ) | AB4: =IF(H4<>"", IF(AND($P4=FALSE, $A4=FALSE), -H4, IF(AND($P4=FALSE, $A4=TRUE), 0, IF($P4=TRUE, (H4 / $R4) * 100 * ($S4 / 100)-H4, ))), ) | AC4: =IF(J4<>"", IF(AND($P4=FALSE, $A4=FALSE), -J4, IF(AND($P4=FALSE, $A4=TRUE), 0, IF($P4=TRUE, (J4 / $R4) * 100 * ($S4 / 100)-J4, ))), ) | AD4: =IF(K4<>"", IF(AND($P4=FALSE, $A4=FALSE), -K4, IF(AND($P4=FALSE, $A4=TRUE), 0, IF($P4=TRUE, (K4 / $R4) * 100 * ($S4 / 100)-K4, ))), ) | AE4: =IF(L4<>"", IF(AND($P4=FALSE, $A4=FALSE), -L4, IF(AND($P4=FALSE, $A4=TRUE), 0, IF($P4=TRUE, (L4 / $R4) * 100 * ($S4 / 100)-L4, ))), ) | AF4: =IF(M4<>"", IF(AND($P4=FALSE, $A4=FALSE), -M4, IF(AND($P4=FALSE, $A4=TRUE), 0, IF($P4=TRUE, (M4 / $R4) * 100 * ($S4 / 100)-M4, ))), ) | AG4: =IF(N4<>"", IF(AND($P4=FALSE, $A4=FALSE), -N4, IF(AND($P4=FALSE, $A4=TRUE), 0, IF($P4=TRUE, (N4 / $R4) * 100 * ($S4 / 100)-N4, ))), )
A5: FALSE | D5: 45174 | E5: NFL | F5: 🏈 23-24 Futures | G5: 2 | P5: FALSE | R5: =IF(G5 <> "",SUM(G5:O5),) -> 2 | S5: 16 | T5: =IFERROR(IF((S5-R5)>R442,"+"&ROUND(((S5-R5)/R5)*100,0),"-"&ROUND((S5/(R5-S5))*100, 0)),) -> +700 | V5: =IF(ISBLANK($D5), "0",) | W5: =IF(ISBLANK($D5), "/",) | Z5: =IF(G5<>"", IF(AND($P5=FALSE, $A5=FALSE), -G5, IF(AND($P5=FALSE, $A5=TRUE), 0, IF($P5=TRUE, (G5 / $R5) * 100 * ($S5 / 100)-G5, ))), ) -> -2 | AA5: =IF(I5<>"", IF(AND($P5=FALSE, $A5=FALSE), -I5, IF(AND($P5=FALSE, $A5=TRUE), 0, IF($P5=TRUE, (I5 / $R5) * 100 * ($S5 / 100)-I5, ))), ) | AB5: =IF(H5<>"", IF(AND($P5=FALSE, $A5=FALSE), -H5, IF(AND($P5=FALSE, $A5=TRUE), 0, IF($P5=TRUE, (H5 / $R5) * 100 * ($S5 / 100)-H5, ))), ) | AC5: =IF(J5<>"", IF(AND($P5=FALSE, $A5=FALSE), -J5, IF(AND($P5=FALSE, $A5=TRUE), 0, IF($P5=TRUE, (J5 / $R5) * 100 * ($S5 / 100)-J5, ))), ) | AD5: =IF(K5<>"", IF(AND($P5=FALSE, $A5=FALSE), -K5, IF(AND($P5=FALSE, $A5=TRUE), 0, IF($P5=TRUE, (K5 / $R5) * 100 * ($S5 / 100)-K5, ))), ) | AE5: =IF(L5<>"", IF(AND($P5=FALSE, $A5=FALSE), -L5, IF(AND($P5=FALSE, $A5=TRUE), 0, IF($P5=TRUE, (L5 / $R5) * 100 * ($S5 / 100)-L5, ))), ) | AF5: =IF(M5<>"", IF(AND($P5=FALSE, $A5=FALSE), -M5, IF(AND($P5=FALSE, $A5=TRUE), 0, IF($P5=TRUE, (M5 / $R5) * 100 * ($S5 / 100)-M5, ))), ) | AG5: =IF(N5<>"", IF(AND($P5=FALSE, $A5=FALSE), -N5, IF(AND($P5=FALSE, $A5=TRUE), 0, IF($P5=TRUE, (N5 / $R5) * 100 * ($S5 / 100)-N5, ))), )
A6: FALSE | P6: FALSE | R6: =IF(G6 <> "",SUM(G6:O6),) | V6: =IF(ISBLANK($D6), "0",) -> 0 | W6: =IF(ISBLANK($D6), "/",) -> / | X6: B. Purdy | Z6: =IF(G6<>"", IF(AND($P6=FALSE, $A6=FALSE), -G6, IF(AND($P6=FALSE, $A6=TRUE), 0, IF($P6=TRUE, (G6 / $R6) * 100 * ($S6 / 100)-G6, ))), ) | AA6: =IF(I6<>"", IF(AND($P6=FALSE, $A6=FALSE), -I6, IF(AND($P6=FALSE, $A6=TRUE), 0, IF($P6=TRUE, (I6 / $R6) * 100 * ($S6 / 100)-I6, ))), ) | AB6: =IF(H6<>"", IF(AND($P6=FALSE, $A6=FALSE), -H6, IF(AND($P6=FALSE, $A6=TRUE), 0, IF($P6=TRUE, (H6 / $R6) * 100 * ($S6 / 100)-H6, ))), ) | AC6: =IF(J6<>"", IF(AND($P6=FALSE, $A6=FALSE), -J6, IF(AND($P6=FALSE, $A6=TRUE), 0, IF($P6=TRUE, (J6 / $R6) * 100 * ($S6 / 100)-J6, ))), ) | AD6: =IF(K6<>"", IF(AND($P6=FALSE, $A6=FALSE), -K6, IF(AND($P6=FALSE, $A6=TRUE), 0, IF($P6=TRUE, (K6 / $R6) * 100 * ($S6 / 100)-K6, ))), ) | AE6: =IF(L6<>"", IF(AND($P6=FALSE, $A6=FALSE), -L6, IF(AND($P6=FALSE, $A6=TRUE), 0, IF($P6=TRUE, (L6 / $R6) * 100 * ($S6 / 100)-L6, ))), ) | AF6: =IF(M6<>"", IF(AND($P6=FALSE, $A6=FALSE), -M6, IF(AND($P6=FALSE, $A6=TRUE), 0, IF($P6=TRUE, (M6 / $R6) * 100 * ($S6 / 100)-M6, ))), ) | AG6: =IF(N6<>"", IF(AND($P6=FALSE, $A6=FALSE), -N6, IF(AND($P6=FALSE, $A6=TRUE), 0, IF($P6=TRUE, (N6 / $R6) * 100 * ($S6 / 100)-N6, ))), )
A7: FALSE | D7: 45174 | E7: NFL | F7: 🏈 23-24 Futures | G7: 1.5 | H7: 1.5 | P7: TRUE | R7: 3 | S7: 10.5 | T7: +250 | Z7: =IF(G7<>"", IF(AND($P7=FALSE, $A7=FALSE), -G7, IF(AND($P7=FALSE, $A7=TRUE), 0, IF($P7=TRUE, (G7 / $R7) * 100 * ($S7 / 100)-G7, ))), ) -> 3.75 | AA7: =IF(I7<>"", IF(AND($P7=FALSE, $A7=FALSE), -I7, IF(AND($P7=FALSE, $A7=TRUE), 0, IF($P7=TRUE, (I7 / $R7) * 100 * ($S7 / 100)-I7, ))), ) | AB7: =IF(H7<>"", IF(AND($P7=FALSE, $A7=FALSE), -H7, IF(AND($P7=FALSE, $A7=TRUE), 0, IF($P7=TRUE, (H7 / $R7) * 100 * ($S7 / 100)-H7, ))), ) -> 3.75 | AC7: =IF(J7<>"", IF(AND($P7=FALSE, $A7=FALSE), -J7, IF(AND($P7=FALSE, $A7=TRUE), 0, IF($P7=TRUE, (J7 / $R7) * 100 * ($S7 / 100)-J7, ))), ) | AD7: =IF(K7<>"", IF(AND($P7=FALSE, $A7=FALSE), -K7, IF(AND($P7=FALSE, $A7=TRUE), 0, IF($P7=TRUE, (K7 / $R7) * 100 * ($S7 / 100)-K7, ))), ) | AE7: =IF(L7<>"", IF(AND($P7=FALSE, $A7=FALSE), -L7, IF(AND($P7=FALSE, $A7=TRUE), 0, IF($P7=TRUE, (L7 / $R7) * 100 * ($S7 / 100)-L7, ))), ) | AF7: =IF(M7<>"", IF(AND($P7=FALSE, $A7=FALSE), -M7, IF(AND($P7=FALSE, $A7=TRUE), 0, IF($P7=TRUE, (M7 / $R7) * 100 * ($S7 / 100)-M7, ))), ) | AG7: =IF(N7<>"", IF(AND($P7=FALSE, $A7=FALSE), -N7, IF(AND($P7=FALSE, $A7=TRUE), 0, IF($P7=TRUE, (N7 / $R7) * 100 * ($S7 / 100)-N7, ))), )
A8: FALSE | P8: FALSE | V8: ✅ | W8: / | X8: 10+ C. McCaffery rush TDs | Z8: =IF(G8<>"", IF(AND($P8=FALSE, $A8=FALSE), -G8, IF(AND($P8=FALSE, $A8=TRUE), 0, IF($P8=TRUE, (G8 / $R8) * 100 * ($S8 / 100)-G8, ))), ) | AA8: =IF(I8<>"", IF(AND($P8=FALSE, $A8=FALSE), -I8, IF(AND($P8=FALSE, $A8=TRUE), 0, IF($P8=TRUE, (I8 / $R8) * 100 * ($S8 / 100)-I8, ))), ) | AB8: =IF(H8<>"", IF(AND($P8=FALSE, $A8=FALSE), -H8, IF(AND($P8=FALSE, $A8=TRUE), 0, IF($P8=TRUE, (H8 / $R8) * 100 * ($S8 / 100)-H8, ))), ) | AC8: =IF(J8<>"", IF(AND($P8=FALSE, $A8=FALSE), -J8, IF(AND($P8=FALSE, $A8=TRUE), 0, IF($P8=TRUE, (J8 / $R8) * 100 * ($S8 / 100)-J8, ))), ) | AD8: =IF(K8<>"", IF(AND($P8=FALSE, $A8=FALSE), -K8, IF(AND($P8=FALSE, $A8=TRUE), 0, IF($P8=TRUE, (K8 / $R8) * 100 * ($S8 / 100)-K8, ))), ) | AE8: =IF(L8<>"", IF(AND($P8=FALSE, $A8=FALSE), -L8, IF(AND($P8=FALSE, $A8=TRUE), 0, IF($P8=TRUE, (L8 / $R8) * 100 * ($S8 / 100)-L8, ))), ) | AF8: =IF(M8<>"", IF(AND($P8=FALSE, $A8=FALSE), -M8, IF(AND($P8=FALSE, $A8=TRUE), 0, IF($P8=TRUE, (M8 / $R8) * 100 * ($S8 / 100)-M8, ))), ) | AG8: =IF(N8<>"", IF(AND($P8=FALSE, $A8=FALSE), -N8, IF(AND($P8=FALSE, $A8=TRUE), 0, IF($P8=TRUE, (N8 / $R8) * 100 * ($S8 / 100)-N8, ))), )
A9: FALSE | D9: 45174 | E9: NFL | F9: 🏈 23-24 Futures | G9: 0.5 | H9: 0.5 | I9: 2 | P9: FALSE | R9: 3 | S9: 57 | T9: +1800 | Z9: =IF(G9<>"", IF(AND($P9=FALSE, $A9=FALSE), -G9, IF(AND($P9=FALSE, $A9=TRUE), 0, IF($P9=TRUE, (G9 / $R9) * 100 * ($S9 / 100)-G9, ))), ) -> -0.5 | AA9: =IF(I9<>"", IF(AND($P9=FALSE, $A9=FALSE), -I9, IF(AND($P9=FALSE, $A9=TRUE), 0, IF($P9=TRUE, (I9 / $R9) * 100 * ($S9 / 100)-I9, ))), ) -> -2 | AB9: =IF(H9<>"", IF(AND($P9=FALSE, $A9=FALSE), -H9, IF(AND($P9=FALSE, $A9=TRUE), 0, IF($P9=TRUE, (H9 / $R9) * 100 * ($S9 / 100)-H9, ))), ) -> -0.5 | AC9: =IF(J9<>"", IF(AND($P9=FALSE, $A9=FALSE), -J9, IF(AND($P9=FALSE, $A9=TRUE), 0, IF($P9=TRUE, (J9 / $R9) * 100 * ($S9 / 100)-J9, ))), ) | AD9: =IF(K9<>"", IF(AND($P9=FALSE, $A9=FALSE), -K9, IF(AND($P9=FALSE, $A9=TRUE), 0, IF($P9=TRUE, (K9 / $R9) * 100 * ($S9 / 100)-K9, ))), ) | AE9: =IF(L9<>"", IF(AND($P9=FALSE, $A9=FALSE), -L9, IF(AND($P9=FALSE, $A9=TRUE), 0, IF($P9=TRUE, (L9 / $R9) * 100 * ($S9 / 100)-L9, ))), ) | AF9: =IF(M9<>"", IF(AND($P9=FALSE, $A9=FALSE), -M9, IF(AND($P9=FALSE, $A9=TRUE), 0, IF($P9=TRUE, (M9 / $R9) * 100 * ($S9 / 100)-M9, ))), ) | AG9: =IF(N9<>"", IF(AND($P9=FALSE, $A9=FALSE), -N9, IF(AND($P9=FALSE, $A9=TRUE), 0, IF($P9=TRUE, (N9 / $R9) * 100 * ($S9 / 100)-N9, ))), )
A10: FALSE | P10: FALSE | V10: ❌ | W10: / | X10: T. Lawrence most total pass yds | Z10: =IF(G10<>"", IF(AND($P10=FALSE, $A10=FALSE), -G10, IF(AND($P10=FALSE, $A10=TRUE), 0, IF($P10=TRUE, (G10 / $R10) * 100 * ($S10 / 100)-G10, ))), ) | AA10: =IF(I10<>"", IF(AND($P10=FALSE, $A10=FALSE), -I10, IF(AND($P10=FALSE, $A10=TRUE), 0, IF($P10=TRUE, (I10 / $R10) * 100 * ($S10 / 100)-I10, ))), ) | AB10: =IF(H10<>"", IF(AND($P10=FALSE, $A10=FALSE), -H10, IF(AND($P10=FALSE, $A10=TRUE), 0, IF($P10=TRUE, (H10 / $R10) * 100 * ($S10 / 100)-H10, ))), ) | AC10: =IF(J10<>"", IF(AND($P10=FALSE, $A10=FALSE), -J10, IF(AND($P10=FALSE, $A10=TRUE), 0, IF($P10=TRUE, (J10 / $R10) * 100 * ($S10 / 100)-J10, ))), ) | AD10: =IF(K10<>"", IF(AND($P10=FALSE, $A10=FALSE), -K10, IF(AND($P10=FALSE, $A10=TRUE), 0, IF($P10=TRUE, (K10 / $R10) * 100 * ($S10 / 100)-K10, ))), ) | AE10: =IF(L10<>"", IF(AND($P10=FALSE, $A10=FALSE), -L10, IF(AND($P10=FALSE, $A10=TRUE), 0, IF($P10=TRUE, (L10 / $R10) * 100 * ($S10 / 100)-L10, ))), ) | AF10: =IF(M10<>"", IF(AND($P10=FALSE, $A10=FALSE), -M10, IF(AND($P10=FALSE, $A10=TRUE), 0, IF($P10=TRUE, (M10 / $R10) * 100 * ($S10 / 100)-M10, ))), ) | AG10: =IF(N10<>"", IF(AND($P10=FALSE, $A10=FALSE), -N10, IF(AND($P10=FALSE, $A10=TRUE), 0, IF($P10=TRUE, (N10 / $R10) * 100 * ($S10 / 100)-N10, ))), )
A11: FALSE | D11: 45174 | E11: NFL | F11: 🏈 23-24 Futures | G11: 1 | H11: 1 | I11: 1 | P11: FALSE | R11: 3 | S11: 25.5 | T11: +750 | Z11: =IF(G11<>"", IF(AND($P11=FALSE, $A11=FALSE), -G11, IF(AND($P11=FALSE, $A11=TRUE), 0, IF($P11=TRUE, (G11 / $R11) * 100 * ($S11 / 100)-G11, ))), ) -> -1 | AA11: =IF(I11<>"", IF(AND($P11=FALSE, $A11=FALSE), -I11, IF(AND($P11=FALSE, $A11=TRUE), 0, IF($P11=TRUE, (I11 / $R11) * 100 * ($S11 / 100)-I11, ))), ) -> -1 | AB11: =IF(H11<>"", IF(AND($P11=FALSE, $A11=FALSE), -H11, IF(AND($P11=FALSE, $A11=TRUE), 0, IF($P11=TRUE, (H11 / $R11) * 100 * ($S11 / 100)-H11, ))), ) -> -1 | AC11: =IF(J11<>"", IF(AND($P11=FALSE, $A11=FALSE), -J11, IF(AND($P11=FALSE, $A11=TRUE), 0, IF($P11=TRUE, (J11 / $R11) * 100 * ($S11 / 100)-J11, ))), ) | AD11: =IF(K11<>"", IF(AND($P11=FALSE, $A11=FALSE), -K11, IF(AND($P11=FALSE, $A11=TRUE), 0, IF($P11=TRUE, (K11 / $R11) * 100 * ($S11 / 100)-K11, ))), ) | AE11: =IF(L11<>"", IF(AND($P11=FALSE, $A11=FALSE), -L11, IF(AND($P11=FALSE, $A11=TRUE), 0, IF($P11=TRUE, (L11 / $R11) * 100 * ($S11 / 100)-L11, ))), ) | AF11: =IF(M11<>"", IF(AND($P11=FALSE, $A11=FALSE), -M11, IF(AND($P11=FALSE, $A11=TRUE), 0, IF($P11=TRUE, (M11 / $R11) * 100 * ($S11 / 100)-M11, ))), ) | AG11: =IF(N11<>"", IF(AND($P11=FALSE, $A11=FALSE), -N11, IF(AND($P11=FALSE, $A11=TRUE), 0, IF($P11=TRUE, (N11 / $R11) * 100 * ($S11 / 100)-N11, ))), )
A12: FALSE | P12: FALSE | V12: ❌ | W12: / | X12: N. Bosa most sacks | Z12: =IF(G12<>"", IF(AND($P12=FALSE, $A12=FALSE), -G12, IF(AND($P12=FALSE, $A12=TRUE), 0, IF($P12=TRUE, (G12 / $R12) * 100 * ($S12 / 100)-G12, ))), ) | AA12: =IF(I12<>"", IF(AND($P12=FALSE, $A12=FALSE), -I12, IF(AND($P12=FALSE, $A12=TRUE), 0, IF($P12=TRUE, (I12 / $R12) * 100 * ($S12 / 100)-I12, ))), ) | AB12: =IF(H12<>"", IF(AND($P12=FALSE, $A12=FALSE), -H12, IF(AND($P12=FALSE, $A12=TRUE), 0, IF($P12=TRUE, (H12 / $R12) * 100 * ($S12 / 100)-H12, ))), ) | AC12: =IF(J12<>"", IF(AND($P12=FALSE, $A12=FALSE), -J12, IF(AND($P12=FALSE, $A12=TRUE), 0, IF($P12=TRUE, (J12 / $R12) * 100 * ($S12 / 100)-J12, ))), ) | AD12: =IF(K12<>"", IF(AND($P12=FALSE, $A12=FALSE), -K12, IF(AND($P12=FALSE, $A12=TRUE), 0, IF($P12=TRUE, (K12 / $R12) * 100 * ($S12 / 100)-K12, ))), ) | AE12: =IF(L12<>"", IF(AND($P12=FALSE, $A12=FALSE), -L12, IF(AND($P12=FALSE, $A12=TRUE), 0, IF($P12=TRUE, (L12 / $R12) * 100 * ($S12 / 100)-L12, ))), ) | AF12: =IF(M12<>"", IF(AND($P12=FALSE, $A12=FALSE), -M12, IF(AND($P12=FALSE, $A12=TRUE), 0, IF($P12=TRUE, (M12 / $R12) * 100 * ($S12 / 100)-M12, ))), ) | AG12: =IF(N12<>"", IF(AND($P12=FALSE, $A12=FALSE), -N12, IF(AND($P12=FALSE, $A12=TRUE), 0, IF($P12=TRUE, (N12 / $R12) * 100 * ($S12 / 100)-N12, ))), )
A13: FALSE | D13: 45174 | E13: NFL | F13: 🏈 23-24 Futures | G13: 1.5 | H13: 1.5 | I13: 1 | P13: FALSE | R13: 4 | S13: 12.89 | T13: +222 | Z13: =IF(G13<>"", IF(AND($P13=FALSE, $A13=FALSE), -G13, IF(AND($P13=FALSE, $A13=TRUE), 0, IF($P13=TRUE, (G13 / $R13) * 100 * ($S13 / 100)-G13, ))), ) -> -1.5 | AA13: =IF(I13<>"", IF(AND($P13=FALSE, $A13=FALSE), -I13, IF(AND($P13=FALSE, $A13=TRUE), 0, IF($P13=TRUE, (I13 / $R13) * 100 * ($S13 / 100)-I13, ))), ) -> -1 | AB13: =IF(H13<>"", IF(AND($P13=FALSE, $A13=FALSE), -H13, IF(AND($P13=FALSE, $A13=TRUE), 0, IF($P13=TRUE, (H13 / $R13) * 100 * ($S13 / 100)-H13, ))), ) -> -1.5 | AC13: =IF(J13<>"", IF(AND($P13=FALSE, $A13=FALSE), -J13, IF(AND($P13=FALSE, $A13=TRUE), 0, IF($P13=TRUE, (J13 / $R13) * 100 * ($S13 / 100)-J13, ))), ) | AD13: =IF(K13<>"", IF(AND($P13=FALSE, $A13=FALSE), -K13, IF(AND($P13=FALSE, $A13=TRUE), 0, IF($P13=TRUE, (K13 / $R13) * 100 * ($S13 / 100)-K13, ))), ) | AE13: =IF(L13<>"", IF(AND($P13=FALSE, $A13=FALSE), -L13, IF(AND($P13=FALSE, $A13=TRUE), 0, IF($P13=TRUE, (L13 / $R13) * 100 * ($S13 / 100)-L13, ))), ) | AF13: =IF(M13<>"", IF(AND($P13=FALSE, $A13=FALSE), -M13, IF(AND($P13=FALSE, $A13=TRUE), 0, IF($P13=TRUE, (M13 / $R13) * 100 * ($S13 / 100)-M13, ))), ) | AG13: =IF(N13<>"", IF(AND($P13=FALSE, $A13=FALSE), -N13, IF(AND($P13=FALSE, $A13=TRUE), 0, IF($P13=TRUE, (N13 / $R13) * 100 * ($S13 / 100)-N13, ))), )
A14: FALSE | P14: FALSE | V14: ❌ | W14: / | X14: 30+ Pass TD - J. Allen | Z14: =IF(G14<>"", IF(AND($P14=FALSE, $A14=FALSE), -G14, IF(AND($P14=FALSE, $A14=TRUE), 0, IF($P14=TRUE, (G14 / $R14) * 100 * ($S14 / 100)-G14, ))), ) | AA14: =IF(I14<>"", IF(AND($P14=FALSE, $A14=FALSE), -I14, IF(AND($P14=FALSE, $A14=TRUE), 0, IF($P14=TRUE, (I14 / $R14) * 100 * ($S14 / 100)-I14, ))), ) | AB14: =IF(H14<>"", IF(AND($P14=FALSE, $A14=FALSE), -H14, IF(AND($P14=FALSE, $A14=TRUE), 0, IF($P14=TRUE, (H14 / $R14) * 100 * ($S14 / 100)-H14, ))), ) | AC14: =IF(J14<>"", IF(AND($P14=FALSE, $A14=FALSE), -J14, IF(AND($P14=FALSE, $A14=TRUE), 0, IF($P14=TRUE, (J14 / $R14) * 100 * ($S14 / 100)-J14, ))), ) | AD14: =IF(K14<>"", IF(AND($P14=FALSE, $A14=FALSE), -K14, IF(AND($P14=FALSE, $A14=TRUE), 0, IF($P14=TRUE, (K14 / $R14) * 100 * ($S14 / 100)-K14, ))), ) | AE14: =IF(L14<>"", IF(AND($P14=FALSE, $A14=FALSE), -L14, IF(AND($P14=FALSE, $A14=TRUE), 0, IF($P14=TRUE, (L14 / $R14) * 100 * ($S14 / 100)-L14, ))), ) | AF14: =IF(M14<>"", IF(AND($P14=FALSE, $A14=FALSE), -M14, IF(AND($P14=FALSE, $A14=TRUE), 0, IF($P14=TRUE, (M14 / $R14) * 100 * ($S14 / 100)-M14, ))), ) | AG14: =IF(N14<>"", IF(AND($P14=FALSE, $A14=FALSE), -N14, IF(AND($P14=FALSE, $A14=TRUE), 0, IF($P14=TRUE, (N14 / $R14) * 100 * ($S14 / 100)-N14, ))), )
A15: FALSE | P15: FALSE | V15: ❌ | W15: / | X15: 30+ Pass TD - J. Burrow | Z15: =IF(G15<>"", IF(AND($P15=FALSE, $A15=FALSE), -G15, IF(AND($P15=FALSE, $A15=TRUE), 0, IF($P15=TRUE, (G15 / $R15) * 100 * ($S15 / 100)-G15, ))), ) | AA15: =IF(I15<>"", IF(AND($P15=FALSE, $A15=FALSE), -I15, IF(AND($P15=FALSE, $A15=TRUE), 0, IF($P15=TRUE, (I15 / $R15) * 100 * ($S15 / 100)-I15, ))), ) | AB15: =IF(H15<>"", IF(AND($P15=FALSE, $A15=FALSE), -H15, IF(AND($P15=FALSE, $A15=TRUE), 0, IF($P15=TRUE, (H15 / $R15) * 100 * ($S15 / 100)-H15, ))), ) | AC15: =IF(J15<>"", IF(AND($P15=FALSE, $A15=FALSE), -J15, IF(AND($P15=FALSE, $A15=TRUE), 0, IF($P15=TRUE, (J15 / $R15) * 100 * ($S15 / 100)-J15, ))), ) | AD15: =IF(K15<>"", IF(AND($P15=FALSE, $A15=FALSE), -K15, IF(AND($P15=FALSE, $A15=TRUE), 0, IF($P15=TRUE, (K15 / $R15) * 100 * ($S15 / 100)-K15, ))), ) | AE15: =IF(L15<>"", IF(AND($P15=FALSE, $A15=FALSE), -L15, IF(AND($P15=FALSE, $A15=TRUE), 0, IF($P15=TRUE, (L15 / $R15) * 100 * ($S15 / 100)-L15, ))), ) | AF15: =IF(M15<>"", IF(AND($P15=FALSE, $A15=FALSE), -M15, IF(AND($P15=FALSE, $A15=TRUE), 0, IF($P15=TRUE, (M15 / $R15) * 100 * ($S15 / 100)-M15, ))), ) | AG15: =IF(N15<>"", IF(AND($P15=FALSE, $A15=FALSE), -N15, IF(AND($P15=FALSE, $A15=TRUE), 0, IF($P15=TRUE, (N15 / $R15) * 100 * ($S15 / 100)-N15, ))), )
A16: FALSE | P16: FALSE | V16: ❌ | W16: / | X16: 30+ Pass TD -J. Herbert | Z16: =IF(G16<>"", IF(AND($P16=FALSE, $A16=FALSE), -G16, IF(AND($P16=FALSE, $A16=TRUE), 0, IF($P16=TRUE, (G16 / $R16) * 100 * ($S16 / 100)-G16, ))), ) | AA16: =IF(I16<>"", IF(AND($P16=FALSE, $A16=FALSE), -I16, IF(AND($P16=FALSE, $A16=TRUE), 0, IF($P16=TRUE, (I16 / $R16) * 100 * ($S16 / 100)-I16, ))), ) | AB16: =IF(H16<>"", IF(AND($P16=FALSE, $A16=FALSE), -H16, IF(AND($P16=FALSE, $A16=TRUE), 0, IF($P16=TRUE, (H16 / $R16) * 100 * ($S16 / 100)-H16, ))), ) | AC16: =IF(J16<>"", IF(AND($P16=FALSE, $A16=FALSE), -J16, IF(AND($P16=FALSE, $A16=TRUE), 0, IF($P16=TRUE, (J16 / $R16) * 100 * ($S16 / 100)-J16, ))), ) | AD16: =IF(K16<>"", IF(AND($P16=FALSE, $A16=FALSE), -K16, IF(AND($P16=FALSE, $A16=TRUE), 0, IF($P16=TRUE, (K16 / $R16) * 100 * ($S16 / 100)-K16, ))), ) | AE16: =IF(L16<>"", IF(AND($P16=FALSE, $A16=FALSE), -L16, IF(AND($P16=FALSE, $A16=TRUE), 0, IF($P16=TRUE, (L16 / $R16) * 100 * ($S16 / 100)-L16, ))), ) | AF16: =IF(M16<>"", IF(AND($P16=FALSE, $A16=FALSE), -M16, IF(AND($P16=FALSE, $A16=TRUE), 0, IF($P16=TRUE, (M16 / $R16) * 100 * ($S16 / 100)-M16, ))), ) | AG16: =IF(N16<>"", IF(AND($P16=FALSE, $A16=FALSE), -N16, IF(AND($P16=FALSE, $A16=TRUE), 0, IF($P16=TRUE, (N16 / $R16) * 100 * ($S16 / 100)-N16, ))), )
A17: FALSE | D17: 45174 | E17: NFL | F17: 🏈 23-24 Futures | G17: 1 | H17: 1 | I17: 1 | P17: FALSE | R17: 3 | S17: 14.82 | T17: +394 | Z17: =IF(G17<>"", IF(AND($P17=FALSE, $A17=FALSE), -G17, IF(AND($P17=FALSE, $A17=TRUE), 0, IF($P17=TRUE, (G17 / $R17) * 100 * ($S17 / 100)-G17, ))), ) -> -1 | AA17: =IF(I17<>"", IF(AND($P17=FALSE, $A17=FALSE), -I17, IF(AND($P17=FALSE, $A17=TRUE), 0, IF($P17=TRUE, (I17 / $R17) * 100 * ($S17 / 100)-I17, ))), ) -> -1 | AB17: =IF(H17<>"", IF(AND($P17=FALSE, $A17=FALSE), -H17, IF(AND($P17=FALSE, $A17=TRUE), 0, IF($P17=TRUE, (H17 / $R17) * 100 * ($S17 / 100)-H17, ))), ) -> -1 | AC17: =IF(J17<>"", IF(AND($P17=FALSE, $A17=FALSE), -J17, IF(AND($P17=FALSE, $A17=TRUE), 0, IF($P17=TRUE, (J17 / $R17) * 100 * ($S17 / 100)-J17, ))), ) | AD17: =IF(K17<>"", IF(AND($P17=FALSE, $A17=FALSE), -K17, IF(AND($P17=FALSE, $A17=TRUE), 0, IF($P17=TRUE, (K17 / $R17) * 100 * ($S17 / 100)-K17, ))), ) | AE17: =IF(L17<>"", IF(AND($P17=FALSE, $A17=FALSE), -L17, IF(AND($P17=FALSE, $A17=TRUE), 0, IF($P17=TRUE, (L17 / $R17) * 100 * ($S17 / 100)-L17, ))), ) | AF17: =IF(M17<>"", IF(AND($P17=FALSE, $A17=FALSE), -M17, IF(AND($P17=FALSE, $A17=TRUE), 0, IF($P17=TRUE, (M17 / $R17) * 100 * ($S17 / 100)-M17, ))), ) | AG17: =IF(N17<>"", IF(AND($P17=FALSE, $A17=FALSE), -N17, IF(AND($P17=FALSE, $A17=TRUE), 0, IF($P17=TRUE, (N17 / $R17) * 100 * ($S17 / 100)-N17, ))), )
A18: FALSE | P18: FALSE | V18: ❌ | W18: / | X18: JAX Jaguars | Z18: =IF(G18<>"", IF(AND($P18=FALSE, $A18=FALSE), -G18, IF(AND($P18=FALSE, $A18=TRUE), 0, IF($P18=TRUE, (G18 / $R18) * 100 * ($S18 / 100)-G18, ))), ) | AA18: =IF(I18<>"", IF(AND($P18=FALSE, $A18=FALSE), -I18, IF(AND($P18=FALSE, $A18=TRUE), 0, IF($P18=TRUE, (I18 / $R18) * 100 * ($S18 / 100)-I18, ))), ) | AB18: =IF(H18<>"", IF(AND($P18=FALSE, $A18=FALSE), -H18, IF(AND($P18=FALSE, $A18=TRUE), 0, IF($P18=TRUE, (H18 / $R18) * 100 * ($S18 / 100)-H18, ))), ) | AC18: =IF(J18<>"", IF(AND($P18=FALSE, $A18=FALSE), -J18, IF(AND($P18=FALSE, $A18=TRUE), 0, IF($P18=TRUE, (J18 / $R18) * 100 * ($S18 / 100)-J18, ))), ) | AD18: =IF(K18<>"", IF(AND($P18=FALSE, $A18=FALSE), -K18, IF(AND($P18=FALSE, $A18=TRUE), 0, IF($P18=TRUE, (K18 / $R18) * 100 * ($S18 / 100)-K18, ))), ) | AE18: =IF(L18<>"", IF(AND($P18=FALSE, $A18=FALSE), -L18, IF(AND($P18=FALSE, $A18=TRUE), 0, IF($P18=TRUE, (L18 / $R18) * 100 * ($S18 / 100)-L18, ))), ) | AF18: =IF(M18<>"", IF(AND($P18=FALSE, $A18=FALSE), -M18, IF(AND($P18=FALSE, $A18=TRUE), 0, IF($P18=TRUE, (M18 / $R18) * 100 * ($S18 / 100)-M18, ))), ) | AG18: =IF(N18<>"", IF(AND($P18=FALSE, $A18=FALSE), -N18, IF(AND($P18=FALSE, $A18=TRUE), 0, IF($P18=TRUE, (N18 / $R18) * 100 * ($S18 / 100)-N18, ))), )
A19: FALSE | P19: FALSE | V19: ❌ | W19: / | X19: PHI Eagles | Z19: =IF(G19<>"", IF(AND($P19=FALSE, $A19=FALSE), -G19, IF(AND($P19=FALSE, $A19=TRUE), 0, IF($P19=TRUE, (G19 / $R19) * 100 * ($S19 / 100)-G19, ))), ) | AA19: =IF(I19<>"", IF(AND($P19=FALSE, $A19=FALSE), -I19, IF(AND($P19=FALSE, $A19=TRUE), 0, IF($P19=TRUE, (I19 / $R19) * 100 * ($S19 / 100)-I19, ))), ) | AB19: =IF(H19<>"", IF(AND($P19=FALSE, $A19=FALSE), -H19, IF(AND($P19=FALSE, $A19=TRUE), 0, IF($P19=TRUE, (H19 / $R19) * 100 * ($S19 / 100)-H19, ))), ) | AC19: =IF(J19<>"", IF(AND($P19=FALSE, $A19=FALSE), -J19, IF(AND($P19=FALSE, $A19=TRUE), 0, IF($P19=TRUE, (J19 / $R19) * 100 * ($S19 / 100)-J19, ))), ) | AD19: =IF(K19<>"", IF(AND($P19=FALSE, $A19=FALSE), -K19, IF(AND($P19=FALSE, $A19=TRUE), 0, IF($P19=TRUE, (K19 / $R19) * 100 * ($S19 / 100)-K19, ))), ) | AE19: =IF(L19<>"", IF(AND($P19=FALSE, $A19=FALSE), -L19, IF(AND($P19=FALSE, $A19=TRUE), 0, IF($P19=TRUE, (L19 / $R19) * 100 * ($S19 / 100)-L19, ))), ) | AF19: =IF(M19<>"", IF(AND($P19=FALSE, $A19=FALSE), -M19, IF(AND($P19=FALSE, $A19=TRUE), 0, IF($P19=TRUE, (M19 / $R19) * 100 * ($S19 / 100)-M19, ))), ) | AG19: =IF(N19<>"", IF(AND($P19=FALSE, $A19=FALSE), -N19, IF(AND($P19=FALSE, $A19=TRUE), 0, IF($P19=TRUE, (N19 / $R19) * 100 * ($S19 / 100)-N19, ))), )
A20: FALSE | P20: FALSE | V20: ✅ | W20: / | X20: SF 49ers | Z20: =IF(G20<>"", IF(AND($P20=FALSE, $A20=FALSE), -G20, IF(AND($P20=FALSE, $A20=TRUE), 0, IF($P20=TRUE, (G20 / $R20) * 100 * ($S20 / 100)-G20, ))), ) | AA20: =IF(I20<>"", IF(AND($P20=FALSE, $A20=FALSE), -I20, IF(AND($P20=FALSE, $A20=TRUE), 0, IF($P20=TRUE, (I20 / $R20) * 100 * ($S20 / 100)-I20, ))), ) | AB20: =IF(H20<>"", IF(AND($P20=FALSE, $A20=FALSE), -H20, IF(AND($P20=FALSE, $A20=TRUE), 0, IF($P20=TRUE, (H20 / $R20) * 100 * ($S20 / 100)-H20, ))), ) | AC20: =IF(J20<>"", IF(AND($P20=FALSE, $A20=FALSE), -J20, IF(AND($P20=FALSE, $A20=TRUE), 0, IF($P20=TRUE, (J20 / $R20) * 100 * ($S20 / 100)-J20, ))), ) | AD20: =IF(K20<>"", IF(AND($P20=FALSE, $A20=FALSE), -K20, IF(AND($P20=FALSE, $A20=TRUE), 0, IF($P20=TRUE, (K20 / $R20) * 100 * ($S20 / 100)-K20, ))), ) | AE20: =IF(L20<>"", IF(AND($P20=FALSE, $A20=FALSE), -L20, IF(AND($P20=FALSE, $A20=TRUE), 0, IF($P20=TRUE, (L20 / $R20) * 100 * ($S20 / 100)-L20, ))), ) | AF20: =IF(M20<>"", IF(AND($P20=FALSE, $A20=FALSE), -M20, IF(AND($P20=FALSE, $A20=TRUE), 0, IF($P20=TRUE, (M20 / $R20) * 100 * ($S20 / 100)-M20, ))), ) | AG20: =IF(N20<>"", IF(AND($P20=FALSE, $A20=FALSE), -N20, IF(AND($P20=FALSE, $A20=TRUE), 0, IF($P20=TRUE, (N20 / $R20) * 100 * ($S20 / 100)-N20, ))), )
A21: FALSE | D21: 45174 | E21: NFL | F21: 🏈 23-24 Futures | G21: 1 | H21: 1 | P21: FALSE | R21: 2 | S21: 5 | T21: +150 | Z21: =IF(G21<>"", IF(AND($P21=FALSE, $A21=FALSE), -G21, IF(AND($P21=FALSE, $A21=TRUE), 0, IF($P21=TRUE, (G21 / $R21) * 100 * ($S21 / 100)-G21, ))), ) -> -1 | AA21: =IF(I21<>"", IF(AND($P21=FALSE, $A21=FALSE), -I21, IF(AND($P21=FALSE, $A21=TRUE), 0, IF($P21=TRUE, (I21 / $R21) * 100 * ($S21 / 100)-I21, ))), ) | AB21: =IF(H21<>"", IF(AND($P21=FALSE, $A21=FALSE), -H21, IF(AND($P21=FALSE, $A21=TRUE), 0, IF($P21=TRUE, (H21 / $R21) * 100 * ($S21 / 100)-H21, ))), ) -> -1 | AC21: =IF(J21<>"", IF(AND($P21=FALSE, $A21=FALSE), -J21, IF(AND($P21=FALSE, $A21=TRUE), 0, IF($P21=TRUE, (J21 / $R21) * 100 * ($S21 / 100)-J21, ))), ) | AD21: =IF(K21<>"", IF(AND($P21=FALSE, $A21=FALSE), -K21, IF(AND($P21=FALSE, $A21=TRUE), 0, IF($P21=TRUE, (K21 / $R21) * 100 * ($S21 / 100)-K21, ))), ) | AE21: =IF(L21<>"", IF(AND($P21=FALSE, $A21=FALSE), -L21, IF(AND($P21=FALSE, $A21=TRUE), 0, IF($P21=TRUE, (L21 / $R21) * 100 * ($S21 / 100)-L21, ))), ) | AF21: =IF(M21<>"", IF(AND($P21=FALSE, $A21=FALSE), -M21, IF(AND($P21=FALSE, $A21=TRUE), 0, IF($P21=TRUE, (M21 / $R21) * 100 * ($S21 / 100)-M21, ))), ) | AG21: =IF(N21<>"", IF(AND($P21=FALSE, $A21=FALSE), -N21, IF(AND($P21=FALSE, $A21=TRUE), 0, IF($P21=TRUE, (N21 / $R21) * 100 * ($S21 / 100)-N21, ))), )
A22: FALSE | P22: FALSE | V22: ❌ | W22: / | X22: 2+ N. Bosa sacks in 3+ Reg Season gm | Z22: =IF(G22<>"", IF(AND($P22=FALSE, $A22=FALSE), -G22, IF(AND($P22=FALSE, $A22=TRUE), 0, IF($P22=TRUE, (G22 / $R22) * 100 * ($S22 / 100)-G22, ))), ) | AA22: =IF(I22<>"", IF(AND($P22=FALSE, $A22=FALSE), -I22, IF(AND($P22=FALSE, $A22=TRUE), 0, IF($P22=TRUE, (I22 / $R22) * 100 * ($S22 / 100)-I22, ))), ) | AB22: =IF(H22<>"", IF(AND($P22=FALSE, $A22=FALSE), -H22, IF(AND($P22=FALSE, $A22=TRUE), 0, IF($P22=TRUE, (H22 / $R22) * 100 * ($S22 / 100)-H22, ))), ) | AC22: =IF(J22<>"", IF(AND($P22=FALSE, $A22=FALSE), -J22, IF(AND($P22=FALSE, $A22=TRUE), 0, IF($P22=TRUE, (J22 / $R22) * 100 * ($S22 / 100)-J22, ))), ) | AD22: =IF(K22<>"", IF(AND($P22=FALSE, $A22=FALSE), -K22, IF(AND($P22=FALSE, $A22=TRUE), 0, IF($P22=TRUE, (K22 / $R22) * 100 * ($S22 / 100)-K22, ))), ) | AE22: =IF(L22<>"", IF(AND($P22=FALSE, $A22=FALSE), -L22, IF(AND($P22=FALSE, $A22=TRUE), 0, IF($P22=TRUE, (L22 / $R22) * 100 * ($S22 / 100)-L22, ))), ) | AF22: =IF(M22<>"", IF(AND($P22=FALSE, $A22=FALSE), -M22, IF(AND($P22=FALSE, $A22=TRUE), 0, IF($P22=TRUE, (M22 / $R22) * 100 * ($S22 / 100)-M22, ))), ) | AG22: =IF(N22<>"", IF(AND($P22=FALSE, $A22=FALSE), -N22, IF(AND($P22=FALSE, $A22=TRUE), 0, IF($P22=TRUE, (N22 / $R22) * 100 * ($S22 / 100)-N22, ))), )
A23: FALSE | D23: 45174 | E23: NFL | F23: 🏈 23-24 Futures | G23: 1 | H23: 1 | P23: FALSE | R23: 2 | S23: 15 | T23: +650 | Z23: =IF(G23<>"", IF(AND($P23=FALSE, $A23=FALSE), -G23, IF(AND($P23=FALSE, $A23=TRUE), 0, IF($P23=TRUE, (G23 / $R23) * 100 * ($S23 / 100)-G23, ))), ) -> -1 | AA23: =IF(I23<>"", IF(AND($P23=FALSE, $A23=FALSE), -I23, IF(AND($P23=FALSE, $A23=TRUE), 0, IF($P23=TRUE, (I23 / $R23) * 100 * ($S23 / 100)-I23, ))), ) | AB23: =IF(H23<>"", IF(AND($P23=FALSE, $A23=FALSE), -H23, IF(AND($P23=FALSE, $A23=TRUE), 0, IF($P23=TRUE, (H23 / $R23) * 100 * ($S23 / 100)-H23, ))), ) -> -1 | AC23: =IF(J23<>"", IF(AND($P23=FALSE, $A23=FALSE), -J23, IF(AND($P23=FALSE, $A23=TRUE), 0, IF($P23=TRUE, (J23 / $R23) * 100 * ($S23 / 100)-J23, ))), ) | AD23: =IF(K23<>"", IF(AND($P23=FALSE, $A23=FALSE), -K23, IF(AND($P23=FALSE, $A23=TRUE), 0, IF($P23=TRUE, (K23 / $R23) * 100 * ($S23 / 100)-K23, ))), ) | AE23: =IF(L23<>"", IF(AND($P23=FALSE, $A23=FALSE), -L23, IF(AND($P23=FALSE, $A23=TRUE), 0, IF($P23=TRUE, (L23 / $R23) * 100 * ($S23 / 100)-L23, ))), ) | AF23: =IF(M23<>"", IF(AND($P23=FALSE, $A23=FALSE), -M23, IF(AND($P23=FALSE, $A23=TRUE), 0, IF($P23=TRUE, (M23 / $R23) * 100 * ($S23 / 100)-M23, ))), ) | AG23: =IF(N23<>"", IF(AND($P23=FALSE, $A23=FALSE), -N23, IF(AND($P23=FALSE, $A23=TRUE), 0, IF($P23=TRUE, (N23 / $R23) * 100 * ($S23 / 100)-N23, ))), )
A24: FALSE | P24: FALSE | V24: ❌ | W24: / | X24: ARI Cardinals - Lowest scoring team | Z24: =IF(G24<>"", IF(AND($P24=FALSE, $A24=FALSE), -G24, IF(AND($P24=FALSE, $A24=TRUE), 0, IF($P24=TRUE, (G24 / $R24) * 100 * ($S24 / 100)-G24, ))), ) | AA24: =IF(I24<>"", IF(AND($P24=FALSE, $A24=FALSE), -I24, IF(AND($P24=FALSE, $A24=TRUE), 0, IF($P24=TRUE, (I24 / $R24) * 100 * ($S24 / 100)-I24, ))), ) | AB24: =IF(H24<>"", IF(AND($P24=FALSE, $A24=FALSE), -H24, IF(AND($P24=FALSE, $A24=TRUE), 0, IF($P24=TRUE, (H24 / $R24) * 100 * ($S24 / 100)-H24, ))), ) | AC24: =IF(J24<>"", IF(AND($P24=FALSE, $A24=FALSE), -J24, IF(AND($P24=FALSE, $A24=TRUE), 0, IF($P24=TRUE, (J24 / $R24) * 100 * ($S24 / 100)-J24, ))), ) | AD24: =IF(K24<>"", IF(AND($P24=FALSE, $A24=FALSE), -K24, IF(AND($P24=FALSE, $A24=TRUE), 0, IF($P24=TRUE, (K24 / $R24) * 100 * ($S24 / 100)-K24, ))), ) | AE24: =IF(L24<>"", IF(AND($P24=FALSE, $A24=FALSE), -L24, IF(AND($P24=FALSE, $A24=TRUE), 0, IF($P24=TRUE, (L24 / $R24) * 100 * ($S24 / 100)-L24, ))), ) | AF24: =IF(M24<>"", IF(AND($P24=FALSE, $A24=FALSE), -M24, IF(AND($P24=FALSE, $A24=TRUE), 0, IF($P24=TRUE, (M24 / $R24) * 100 * ($S24 / 100)-M24, ))), ) | AG24: =IF(N24<>"", IF(AND($P24=FALSE, $A24=FALSE), -N24, IF(AND($P24=FALSE, $A24=TRUE), 0, IF($P24=TRUE, (N24 / $R24) * 100 * ($S24 / 100)-N24, ))), )
A25: FALSE | D25: 45174 | E25: NFL | F25: 🏈 23-24 Futures | G25: 1 | H25: 1 | P25: FALSE | R25: 2 | S25: 18 | T25: +800 | Z25: =IF(G25<>"", IF(AND($P25=FALSE, $A25=FALSE), -G25, IF(AND($P25=FALSE, $A25=TRUE), 0, IF($P25=TRUE, (G25 / $R25) * 100 * ($S25 / 100)-G25, ))), ) -> -1 | AA25: =IF(I25<>"", IF(AND($P25=FALSE, $A25=FALSE), -I25, IF(AND($P25=FALSE, $A25=TRUE), 0, IF($P25=TRUE, (I25 / $R25) * 100 * ($S25 / 100)-I25, ))), ) | AB25: =IF(H25<>"", IF(AND($P25=FALSE, $A25=FALSE), -H25, IF(AND($P25=FALSE, $A25=TRUE), 0, IF($P25=TRUE, (H25 / $R25) * 100 * ($S25 / 100)-H25, ))), ) -> -1 | AC25: =IF(J25<>"", IF(AND($P25=FALSE, $A25=FALSE), -J25, IF(AND($P25=FALSE, $A25=TRUE), 0, IF($P25=TRUE, (J25 / $R25) * 100 * ($S25 / 100)-J25, ))), ) | AD25: =IF(K25<>"", IF(AND($P25=FALSE, $A25=FALSE), -K25, IF(AND($P25=FALSE, $A25=TRUE), 0, IF($P25=TRUE, (K25 / $R25) * 100 * ($S25 / 100)-K25, ))), ) | AE25: =IF(L25<>"", IF(AND($P25=FALSE, $A25=FALSE), -L25, IF(AND($P25=FALSE, $A25=TRUE), 0, IF($P25=TRUE, (L25 / $R25) * 100 * ($S25 / 100)-L25, ))), ) | AF25: =IF(M25<>"", IF(AND($P25=FALSE, $A25=FALSE), -M25, IF(AND($P25=FALSE, $A25=TRUE), 0, IF($P25=TRUE, (M25 / $R25) * 100 * ($S25 / 100)-M25, ))), ) | AG25: =IF(N25<>"", IF(AND($P25=FALSE, $A25=FALSE), -N25, IF(AND($P25=FALSE, $A25=TRUE), 0, IF($P25=TRUE, (N25 / $R25) * 100 * ($S25 / 100)-N25, ))), )
A26: FALSE | P26: FALSE | V26: ❌ | W26: / | X26: TB Buccanears- Lowest scoring team | Z26: =IF(G26<>"", IF(AND($P26=FALSE, $A26=FALSE), -G26, IF(AND($P26=FALSE, $A26=TRUE), 0, IF($P26=TRUE, (G26 / $R26) * 100 * ($S26 / 100)-G26, ))), ) | AA26: =IF(I26<>"", IF(AND($P26=FALSE, $A26=FALSE), -I26, IF(AND($P26=FALSE, $A26=TRUE), 0, IF($P26=TRUE, (I26 / $R26) * 100 * ($S26 / 100)-I26, ))), ) | AB26: =IF(H26<>"", IF(AND($P26=FALSE, $A26=FALSE), -H26, IF(AND($P26=FALSE, $A26=TRUE), 0, IF($P26=TRUE, (H26 / $R26) * 100 * ($S26 / 100)-H26, ))), ) | AC26: =IF(J26<>"", IF(AND($P26=FALSE, $A26=FALSE), -J26, IF(AND($P26=FALSE, $A26=TRUE), 0, IF($P26=TRUE, (J26 / $R26) * 100 * ($S26 / 100)-J26, ))), ) | AD26: =IF(K26<>"", IF(AND($P26=FALSE, $A26=FALSE), -K26, IF(AND($P26=FALSE, $A26=TRUE), 0, IF($P26=TRUE, (K26 / $R26) * 100 * ($S26 / 100)-K26, ))), ) | AE26: =IF(L26<>"", IF(AND($P26=FALSE, $A26=FALSE), -L26, IF(AND($P26=FALSE, $A26=TRUE), 0, IF($P26=TRUE, (L26 / $R26) * 100 * ($S26 / 100)-L26, ))), ) | AF26: =IF(M26<>"", IF(AND($P26=FALSE, $A26=FALSE), -M26, IF(AND($P26=FALSE, $A26=TRUE), 0, IF($P26=TRUE, (M26 / $R26) * 100 * ($S26 / 100)-M26, ))), ) | AG26: =IF(N26<>"", IF(AND($P26=FALSE, $A26=FALSE), -N26, IF(AND($P26=FALSE, $A26=TRUE), 0, IF($P26=TRUE, (N26 / $R26) * 100 * ($S26 / 100)-N26, ))), )
A27: FALSE | D27: 45174 | E27: NFL | F27: 🏈 23-24 Futures | G27: 1 | H27: 1 | P27: FALSE | R27: 2 | S27: 14 | T27: +600 | Z27: =IF(G27<>"", IF(AND($P27=FALSE, $A27=FALSE), -G27, IF(AND($P27=FALSE, $A27=TRUE), 0, IF($P27=TRUE, (G27 / $R27) * 100 * ($S27 / 100)-G27, ))), ) -> -1 | AA27: =IF(I27<>"", IF(AND($P27=FALSE, $A27=FALSE), -I27, IF(AND($P27=FALSE, $A27=TRUE), 0, IF($P27=TRUE, (I27 / $R27) * 100 * ($S27 / 100)-I27, ))), ) | AB27: =IF(H27<>"", IF(AND($P27=FALSE, $A27=FALSE), -H27, IF(AND($P27=FALSE, $A27=TRUE), 0, IF($P27=TRUE, (H27 / $R27) * 100 * ($S27 / 100)-H27, ))), ) -> -1 | AC27: =IF(J27<>"", IF(AND($P27=FALSE, $A27=FALSE), -J27, IF(AND($P27=FALSE, $A27=TRUE), 0, IF($P27=TRUE, (J27 / $R27) * 100 * ($S27 / 100)-J27, ))), ) | AD27: =IF(K27<>"", IF(AND($P27=FALSE, $A27=FALSE), -K27, IF(AND($P27=FALSE, $A27=TRUE), 0, IF($P27=TRUE, (K27 / $R27) * 100 * ($S27 / 100)-K27, ))), ) | AE27: =IF(L27<>"", IF(AND($P27=FALSE, $A27=FALSE), -L27, IF(AND($P27=FALSE, $A27=TRUE), 0, IF($P27=TRUE, (L27 / $R27) * 100 * ($S27 / 100)-L27, ))), ) | AF27: =IF(M27<>"", IF(AND($P27=FALSE, $A27=FALSE), -M27, IF(AND($P27=FALSE, $A27=TRUE), 0, IF($P27=TRUE, (M27 / $R27) * 100 * ($S27 / 100)-M27, ))), ) | AG27: =IF(N27<>"", IF(AND($P27=FALSE, $A27=FALSE), -N27, IF(AND($P27=FALSE, $A27=TRUE), 0, IF($P27=TRUE, (N27 / $R27) * 100 * ($S27 / 100)-N27, ))), )
A28: FALSE | P28: FALSE | V28: ❌ | W28: / | X28: SF 49ers - Fewest points conceded | Z28: =IF(G28<>"", IF(AND($P28=FALSE, $A28=FALSE), -G28, IF(AND($P28=FALSE, $A28=TRUE), 0, IF($P28=TRUE, (G28 / $R28) * 100 * ($S28 / 100)-G28, ))), ) | AA28: =IF(I28<>"", IF(AND($P28=FALSE, $A28=FALSE), -I28, IF(AND($P28=FALSE, $A28=TRUE), 0, IF($P28=TRUE, (I28 / $R28) * 100 * ($S28 / 100)-I28, ))), ) | AB28: =IF(H28<>"", IF(AND($P28=FALSE, $A28=FALSE), -H28, IF(AND($P28=FALSE, $A28=TRUE), 0, IF($P28=TRUE, (H28 / $R28) * 100 * ($S28 / 100)-H28, ))), ) | AC28: =IF(J28<>"", IF(AND($P28=FALSE, $A28=FALSE), -J28, IF(AND($P28=FALSE, $A28=TRUE), 0, IF($P28=TRUE, (J28 / $R28) * 100 * ($S28 / 100)-J28, ))), ) | AD28: =IF(K28<>"", IF(AND($P28=FALSE, $A28=FALSE), -K28, IF(AND($P28=FALSE, $A28=TRUE), 0, IF($P28=TRUE, (K28 / $R28) * 100 * ($S28 / 100)-K28, ))), ) | AE28: =IF(L28<>"", IF(AND($P28=FALSE, $A28=FALSE), -L28, IF(AND($P28=FALSE, $A28=TRUE), 0, IF($P28=TRUE, (L28 / $R28) * 100 * ($S28 / 100)-L28, ))), ) | AF28: =IF(M28<>"", IF(AND($P28=FALSE, $A28=FALSE), -M28, IF(AND($P28=FALSE, $A28=TRUE), 0, IF($P28=TRUE, (M28 / $R28) * 100 * ($S28 / 100)-M28, ))), ) | AG28: =IF(N28<>"", IF(AND($P28=FALSE, $A28=FALSE), -N28, IF(AND($P28=FALSE, $A28=TRUE), 0, IF($P28=TRUE, (N28 / $R28) * 100 * ($S28 / 100)-N28, ))), )
A29: FALSE | D29: 45243 | E29: NFL | F29: 🏈 23-24 Wk 10 | G29: 1 | H29: 0.5 | P29: FALSE | R29: 1.5 | S29: 6.75 | T29: +350 | Z29: =IF(G29<>"", IF(AND($P29=FALSE, $A29=FALSE), -G29, IF(AND($P29=FALSE, $A29=TRUE), 0, IF($P29=TRUE, (G29 / $R29) * 100 * ($S29 / 100)-G29, ))), ) -> -1 | AA29: =IF(I29<>"", IF(AND($P29=FALSE, $A29=FALSE), -I29, IF(AND($P29=FALSE, $A29=TRUE), 0, IF($P29=TRUE, (I29 / $R29) * 100 * ($S29 / 100)-I29, ))), ) | AB29: =IF(H29<>"", IF(AND($P29=FALSE, $A29=FALSE), -H29, IF(AND($P29=FALSE, $A29=TRUE), 0, IF($P29=TRUE, (H29 / $R29) * 100 * ($S29 / 100)-H29, ))), ) -> -0.5 | AC29: =IF(J29<>"", IF(AND($P29=FALSE, $A29=FALSE), -J29, IF(AND($P29=FALSE, $A29=TRUE), 0, IF($P29=TRUE, (J29 / $R29) * 100 * ($S29 / 100)-J29, ))), ) | AD29: =IF(K29<>"", IF(AND($P29=FALSE, $A29=FALSE), -K29, IF(AND($P29=FALSE, $A29=TRUE), 0, IF($P29=TRUE, (K29 / $R29) * 100 * ($S29 / 100)-K29, ))), ) | AE29: =IF(L29<>"", IF(AND($P29=FALSE, $A29=FALSE), -L29, IF(AND($P29=FALSE, $A29=TRUE), 0, IF($P29=TRUE, (L29 / $R29) * 100 * ($S29 / 100)-L29, ))), ) | AF29: =IF(M29<>"", IF(AND($P29=FALSE, $A29=FALSE), -M29, IF(AND($P29=FALSE, $A29=TRUE), 0, IF($P29=TRUE, (M29 / $R29) * 100 * ($S29 / 100)-M29, ))), ) | AG29: =IF(N29<>"", IF(AND($P29=FALSE, $A29=FALSE), -N29, IF(AND($P29=FALSE, $A29=TRUE), 0, IF($P29=TRUE, (N29 / $R29) * 100 * ($S29 / 100)-N29, ))), )
A30: FALSE | P30: FALSE | V30: ❌ | W30: / | X30: C. McCaffery - Most rush TDs 2023 | Z30: =IF(G30<>"", IF(AND($P30=FALSE, $A30=FALSE), -G30, IF(AND($P30=FALSE, $A30=TRUE), 0, IF($P30=TRUE, (G30 / $R30) * 100 * ($S30 / 100)-G30, ))), ) | AA30: =IF(I30<>"", IF(AND($P30=FALSE, $A30=FALSE), -I30, IF(AND($P30=FALSE, $A30=TRUE), 0, IF($P30=TRUE, (I30 / $R30) * 100 * ($S30 / 100)-I30, ))), ) | AB30: =IF(H30<>"", IF(AND($P30=FALSE, $A30=FALSE), -H30, IF(AND($P30=FALSE, $A30=TRUE), 0, IF($P30=TRUE, (H30 / $R30) * 100 * ($S30 / 100)-H30, ))), ) | AC30: =IF(J30<>"", IF(AND($P30=FALSE, $A30=FALSE), -J30, IF(AND($P30=FALSE, $A30=TRUE), 0, IF($P30=TRUE, (J30 / $R30) * 100 * ($S30 / 100)-J30, ))), ) | AD30: =IF(K30<>"", IF(AND($P30=FALSE, $A30=FALSE), -K30, IF(AND($P30=FALSE, $A30=TRUE), 0, IF($P30=TRUE, (K30 / $R30) * 100 * ($S30 / 100)-K30, ))), ) | AE30: =IF(L30<>"", IF(AND($P30=FALSE, $A30=FALSE), -L30, IF(AND($P30=FALSE, $A30=TRUE), 0, IF($P30=TRUE, (L30 / $R30) * 100 * ($S30 / 100)-L30, ))), ) | AF30: =IF(M30<>"", IF(AND($P30=FALSE, $A30=FALSE), -M30, IF(AND($P30=FALSE, $A30=TRUE), 0, IF($P30=TRUE, (M30 / $R30) * 100 * ($S30 / 100)-M30, ))), ) | AG30: =IF(N30<>"", IF(AND($P30=FALSE, $A30=FALSE), -N30, IF(AND($P30=FALSE, $A30=TRUE), 0, IF($P30=TRUE, (N30 / $R30) * 100 * ($S30 / 100)-N30, ))), )
A31: FALSE | D31: 45243 | E31: NFL | F31: 🏈 23-24 Wk 10 | G31: 3 | H31: 1.5 | P31: TRUE | R31: 4.5 | S31: 13.5 | T31: +200 | Z31: =IF(G31<>"", IF(AND($P31=FALSE, $A31=FALSE), -G31, IF(AND($P31=FALSE, $A31=TRUE), 0, IF($P31=TRUE, (G31 / $R31) * 100 * ($S31 / 100)-G31, ))), ) -> 6 | AA31: =IF(I31<>"", IF(AND($P31=FALSE, $A31=FALSE), -I31, IF(AND($P31=FALSE, $A31=TRUE), 0, IF($P31=TRUE, (I31 / $R31) * 100 * ($S31 / 100)-I31, ))), ) | AB31: =IF(H31<>"", IF(AND($P31=FALSE, $A31=FALSE), -H31, IF(AND($P31=FALSE, $A31=TRUE), 0, IF($P31=TRUE, (H31 / $R31) * 100 * ($S31 / 100)-H31, ))), ) -> 3 | AC31: =IF(J31<>"", IF(AND($P31=FALSE, $A31=FALSE), -J31, IF(AND($P31=FALSE, $A31=TRUE), 0, IF($P31=TRUE, (J31 / $R31) * 100 * ($S31 / 100)-J31, ))), ) | AD31: =IF(K31<>"", IF(AND($P31=FALSE, $A31=FALSE), -K31, IF(AND($P31=FALSE, $A31=TRUE), 0, IF($P31=TRUE, (K31 / $R31) * 100 * ($S31 / 100)-K31, ))), ) | AE31: =IF(L31<>"", IF(AND($P31=FALSE, $A31=FALSE), -L31, IF(AND($P31=FALSE, $A31=TRUE), 0, IF($P31=TRUE, (L31 / $R31) * 100 * ($S31 / 100)-L31, ))), ) | AF31: =IF(M31<>"", IF(AND($P31=FALSE, $A31=FALSE), -M31, IF(AND($P31=FALSE, $A31=TRUE), 0, IF($P31=TRUE, (M31 / $R31) * 100 * ($S31 / 100)-M31, ))), ) | AG31: =IF(N31<>"", IF(AND($P31=FALSE, $A31=FALSE), -N31, IF(AND($P31=FALSE, $A31=TRUE), 0, IF($P31=TRUE, (N31 / $R31) * 100 * ($S31 / 100)-N31, ))), )
A32: FALSE | P32: FALSE | V32: ✅ | W32: / | X32: C. McCaffery - Most rush Yds 2023 | Z32: =IF(G32<>"", IF(AND($P32=FALSE, $A32=FALSE), -G32, IF(AND($P32=FALSE, $A32=TRUE), 0, IF($P32=TRUE, (G32 / $R32) * 100 * ($S32 / 100)-G32, ))), ) | AA32: =IF(I32<>"", IF(AND($P32=FALSE, $A32=FALSE), -I32, IF(AND($P32=FALSE, $A32=TRUE), 0, IF($P32=TRUE, (I32 / $R32) * 100 * ($S32 / 100)-I32, ))), ) | AB32: =IF(H32<>"", IF(AND($P32=FALSE, $A32=FALSE), -H32, IF(AND($P32=FALSE, $A32=TRUE), 0, IF($P32=TRUE, (H32 / $R32) * 100 * ($S32 / 100)-H32, ))), ) | AC32: =IF(J32<>"", IF(AND($P32=FALSE, $A32=FALSE), -J32, IF(AND($P32=FALSE, $A32=TRUE), 0, IF($P32=TRUE, (J32 / $R32) * 100 * ($S32 / 100)-J32, ))), ) | AD32: =IF(K32<>"", IF(AND($P32=FALSE, $A32=FALSE), -K32, IF(AND($P32=FALSE, $A32=TRUE), 0, IF($P32=TRUE, (K32 / $R32) * 100 * ($S32 / 100)-K32, ))), ) | AE32: =IF(L32<>"", IF(AND($P32=FALSE, $A32=FALSE), -L32, IF(AND($P32=FALSE, $A32=TRUE), 0, IF($P32=TRUE, (L32 / $R32) * 100 * ($S32 / 100)-L32, ))), ) | AF32: =IF(M32<>"", IF(AND($P32=FALSE, $A32=FALSE), -M32, IF(AND($P32=FALSE, $A32=TRUE), 0, IF($P32=TRUE, (M32 / $R32) * 100 * ($S32 / 100)-M32, ))), ) | AG32: =IF(N32<>"", IF(AND($P32=FALSE, $A32=FALSE), -N32, IF(AND($P32=FALSE, $A32=TRUE), 0, IF($P32=TRUE, (N32 / $R32) * 100 * ($S32 / 100)-N32, ))), )
A33: FALSE | D33: 45260 | E33: NFL | F33: 🏈 23-24 Wk 13 | G33: 2 | H33: 1 | P33: FALSE | R33: 3 | S33: 12 | T33: +300 | Z33: =IF(G33<>"", IF(AND($P33=FALSE, $A33=FALSE), -G33, IF(AND($P33=FALSE, $A33=TRUE), 0, IF($P33=TRUE, (G33 / $R33) * 100 * ($S33 / 100)-G33, ))), ) -> -2 | AA33: =IF(I33<>"", IF(AND($P33=FALSE, $A33=FALSE), -I33, IF(AND($P33=FALSE, $A33=TRUE), 0, IF($P33=TRUE, (I33 / $R33) * 100 * ($S33 / 100)-I33, ))), ) | AB33: =IF(H33<>"", IF(AND($P33=FALSE, $A33=FALSE), -H33, IF(AND($P33=FALSE, $A33=TRUE), 0, IF($P33=TRUE, (H33 / $R33) * 100 * ($S33 / 100)-H33, ))), ) -> -1 | AC33: =IF(J33<>"", IF(AND($P33=FALSE, $A33=FALSE), -J33, IF(AND($P33=FALSE, $A33=TRUE), 0, IF($P33=TRUE, (J33 / $R33) * 100 * ($S33 / 100)-J33, ))), ) | AD33: =IF(K33<>"", IF(AND($P33=FALSE, $A33=FALSE), -K33, IF(AND($P33=FALSE, $A33=TRUE), 0, IF($P33=TRUE, (K33 / $R33) * 100 * ($S33 / 100)-K33, ))), ) | AE33: =IF(L33<>"", IF(AND($P33=FALSE, $A33=FALSE), -L33, IF(AND($P33=FALSE, $A33=TRUE), 0, IF($P33=TRUE, (L33 / $R33) * 100 * ($S33 / 100)-L33, ))), ) | AF33: =IF(M33<>"", IF(AND($P33=FALSE, $A33=FALSE), -M33, IF(AND($P33=FALSE, $A33=TRUE), 0, IF($P33=TRUE, (M33 / $R33) * 100 * ($S33 / 100)-M33, ))), ) | AG33: =IF(N33<>"", IF(AND($P33=FALSE, $A33=FALSE), -N33, IF(AND($P33=FALSE, $A33=TRUE), 0, IF($P33=TRUE, (N33 / $R33) * 100 * ($S33 / 100)-N33, ))), )
A34: FALSE | P34: FALSE | V34: ❌ | W34: / | X34: YES - 49ers to run the "Bird Gountlet" | Z34: =IF(G34<>"", IF(AND($P34=FALSE, $A34=FALSE), -G34, IF(AND($P34=FALSE, $A34=TRUE), 0, IF($P34=TRUE, (G34 / $R34) * 100 * ($S34 / 100)-G34, ))), ) | AA34: =IF(I34<>"", IF(AND($P34=FALSE, $A34=FALSE), -I34, IF(AND($P34=FALSE, $A34=TRUE), 0, IF($P34=TRUE, (I34 / $R34) * 100 * ($S34 / 100)-I34, ))), ) | AB34: =IF(H34<>"", IF(AND($P34=FALSE, $A34=FALSE), -H34, IF(AND($P34=FALSE, $A34=TRUE), 0, IF($P34=TRUE, (H34 / $R34) * 100 * ($S34 / 100)-H34, ))), ) | AC34: =IF(J34<>"", IF(AND($P34=FALSE, $A34=FALSE), -J34, IF(AND($P34=FALSE, $A34=TRUE), 0, IF($P34=TRUE, (J34 / $R34) * 100 * ($S34 / 100)-J34, ))), ) | AD34: =IF(K34<>"", IF(AND($P34=FALSE, $A34=FALSE), -K34, IF(AND($P34=FALSE, $A34=TRUE), 0, IF($P34=TRUE, (K34 / $R34) * 100 * ($S34 / 100)-K34, ))), ) | AE34: =IF(L34<>"", IF(AND($P34=FALSE, $A34=FALSE), -L34, IF(AND($P34=FALSE, $A34=TRUE), 0, IF($P34=TRUE, (L34 / $R34) * 100 * ($S34 / 100)-L34, ))), ) | AF34: =IF(M34<>"", IF(AND($P34=FALSE, $A34=FALSE), -M34, IF(AND($P34=FALSE, $A34=TRUE), 0, IF($P34=TRUE, (M34 / $R34) * 100 * ($S34 / 100)-M34, ))), ) | AG34: =IF(N34<>"", IF(AND($P34=FALSE, $A34=FALSE), -N34, IF(AND($P34=FALSE, $A34=TRUE), 0, IF($P34=TRUE, (N34 / $R34) * 100 * ($S34 / 100)-N34, ))), )
A35: FALSE | D35: 45235 | E35: NBA | F35: 🏀 23-24 11(Nov) | G35: 2 | H35: 1 | I35: 2 | P35: FALSE | R35: 5 | S35: 12.13 | T35: +143 | Z35: =IF(G35<>"", IF(AND($P35=FALSE, $A35=FALSE), -G35, IF(AND($P35=FALSE, $A35=TRUE), 0, IF($P35=TRUE, (G35 / $R35) * 100 * ($S35 / 100)-G35, ))), ) -> -2 | AA35: =IF(I35<>"", IF(AND($P35=FALSE, $A35=FALSE), -I35, IF(AND($P35=FALSE, $A35=TRUE), 0, IF($P35=TRUE, (I35 / $R35) * 100 * ($S35 / 100)-I35, ))), ) -> -2 | AB35: =IF(H35<>"", IF(AND($P35=FALSE, $A35=FALSE), -H35, IF(AND($P35=FALSE, $A35=TRUE), 0, IF($P35=TRUE, (H35 / $R35) * 100 * ($S35 / 100)-H35, ))), ) -> -1 | AC35: =IF(J35<>"", IF(AND($P35=FALSE, $A35=FALSE), -J35, IF(AND($P35=FALSE, $A35=TRUE), 0, IF($P35=TRUE, (J35 / $R35) * 100 * ($S35 / 100)-J35, ))), ) | AD35: =IF(K35<>"", IF(AND($P35=FALSE, $A35=FALSE), -K35, IF(AND($P35=FALSE, $A35=TRUE), 0, IF($P35=TRUE, (K35 / $R35) * 100 * ($S35 / 100)-K35, ))), ) | AE35: =IF(L35<>"", IF(AND($P35=FALSE, $A35=FALSE), -L35, IF(AND($P35=FALSE, $A35=TRUE), 0, IF($P35=TRUE, (L35 / $R35) * 100 * ($S35 / 100)-L35, ))), ) | AF35: =IF(M35<>"", IF(AND($P35=FALSE, $A35=FALSE), -M35, IF(AND($P35=FALSE, $A35=TRUE), 0, IF($P35=TRUE, (M35 / $R35) * 100 * ($S35 / 100)-M35, ))), ) | AG35: =IF(N35<>"", IF(AND($P35=FALSE, $A35=FALSE), -N35, IF(AND($P35=FALSE, $A35=TRUE), 0, IF($P35=TRUE, (N35 / $R35) * 100 * ($S35 / 100)-N35, ))), )
A36: FALSE | P36: FALSE | V36: ❌ | W36: / | X36: 25+ L. Doncic p | Z36: =IF(G36<>"", IF(AND($P36=FALSE, $A36=FALSE), -G36, IF(AND($P36=FALSE, $A36=TRUE), 0, IF($P36=TRUE, (G36 / $R36) * 100 * ($S36 / 100)-G36, ))), ) | AA36: =IF(I36<>"", IF(AND($P36=FALSE, $A36=FALSE), -I36, IF(AND($P36=FALSE, $A36=TRUE), 0, IF($P36=TRUE, (I36 / $R36) * 100 * ($S36 / 100)-I36, ))), ) | AB36: =IF(H36<>"", IF(AND($P36=FALSE, $A36=FALSE), -H36, IF(AND($P36=FALSE, $A36=TRUE), 0, IF($P36=TRUE, (H36 / $R36) * 100 * ($S36 / 100)-H36, ))), ) | AC36: =IF(J36<>"", IF(AND($P36=FALSE, $A36=FALSE), -J36, IF(AND($P36=FALSE, $A36=TRUE), 0, IF($P36=TRUE, (J36 / $R36) * 100 * ($S36 / 100)-J36, ))), ) | AD36: =IF(K36<>"", IF(AND($P36=FALSE, $A36=FALSE), -K36, IF(AND($P36=FALSE, $A36=TRUE), 0, IF($P36=TRUE, (K36 / $R36) * 100 * ($S36 / 100)-K36, ))), ) | AE36: =IF(L36<>"", IF(AND($P36=FALSE, $A36=FALSE), -L36, IF(AND($P36=FALSE, $A36=TRUE), 0, IF($P36=TRUE, (L36 / $R36) * 100 * ($S36 / 100)-L36, ))), ) | AF36: =IF(M36<>"", IF(AND($P36=FALSE, $A36=FALSE), -M36, IF(AND($P36=FALSE, $A36=TRUE), 0, IF($P36=TRUE, (M36 / $R36) * 100 * ($S36 / 100)-M36, ))), ) | AG36: =IF(N36<>"", IF(AND($P36=FALSE, $A36=FALSE), -N36, IF(AND($P36=FALSE, $A36=TRUE), 0, IF($P36=TRUE, (N36 / $R36) * 100 * ($S36 / 100)-N36, ))), )
A37: FALSE | P37: FALSE | V37: ✅ | W37: / | X37: 8+ L. Doncic a | Z37: =IF(G37<>"", IF(AND($P37=FALSE, $A37=FALSE), -G37, IF(AND($P37=FALSE, $A37=TRUE), 0, IF($P37=TRUE, (G37 / $R37) * 100 * ($S37 / 100)-G37, ))), ) | AA37: =IF(I37<>"", IF(AND($P37=FALSE, $A37=FALSE), -I37, IF(AND($P37=FALSE, $A37=TRUE), 0, IF($P37=TRUE, (I37 / $R37) * 100 * ($S37 / 100)-I37, ))), ) | AB37: =IF(H37<>"", IF(AND($P37=FALSE, $A37=FALSE), -H37, IF(AND($P37=FALSE, $A37=TRUE), 0, IF($P37=TRUE, (H37 / $R37) * 100 * ($S37 / 100)-H37, ))), ) | AC37: =IF(J37<>"", IF(AND($P37=FALSE, $A37=FALSE), -J37, IF(AND($P37=FALSE, $A37=TRUE), 0, IF($P37=TRUE, (J37 / $R37) * 100 * ($S37 / 100)-J37, ))), ) | AD37: =IF(K37<>"", IF(AND($P37=FALSE, $A37=FALSE), -K37, IF(AND($P37=FALSE, $A37=TRUE), 0, IF($P37=TRUE, (K37 / $R37) * 100 * ($S37 / 100)-K37, ))), ) | AE37: =IF(L37<>"", IF(AND($P37=FALSE, $A37=FALSE), -L37, IF(AND($P37=FALSE, $A37=TRUE), 0, IF($P37=TRUE, (L37 / $R37) * 100 * ($S37 / 100)-L37, ))), ) | AF37: =IF(M37<>"", IF(AND($P37=FALSE, $A37=FALSE), -M37, IF(AND($P37=FALSE, $A37=TRUE), 0, IF($P37=TRUE, (M37 / $R37) * 100 * ($S37 / 100)-M37, ))), ) | AG37: =IF(N37<>"", IF(AND($P37=FALSE, $A37=FALSE), -N37, IF(AND($P37=FALSE, $A37=TRUE), 0, IF($P37=TRUE, (N37 / $R37) * 100 * ($S37 / 100)-N37, ))), )
A38: FALSE | P38: FALSE | V38: ✅ | W38: / | X38: 8+ L. Doncic r | Z38: =IF(G38<>"", IF(AND($P38=FALSE, $A38=FALSE), -G38, IF(AND($P38=FALSE, $A38=TRUE), 0, IF($P38=TRUE, (G38 / $R38) * 100 * ($S38 / 100)-G38, ))), ) | AA38: =IF(I38<>"", IF(AND($P38=FALSE, $A38=FALSE), -I38, IF(AND($P38=FALSE, $A38=TRUE), 0, IF($P38=TRUE, (I38 / $R38) * 100 * ($S38 / 100)-I38, ))), ) | AB38: =IF(H38<>"", IF(AND($P38=FALSE, $A38=FALSE), -H38, IF(AND($P38=FALSE, $A38=TRUE), 0, IF($P38=TRUE, (H38 / $R38) * 100 * ($S38 / 100)-H38, ))), ) | AC38: =IF(J38<>"", IF(AND($P38=FALSE, $A38=FALSE), -J38, IF(AND($P38=FALSE, $A38=TRUE), 0, IF($P38=TRUE, (J38 / $R38) * 100 * ($S38 / 100)-J38, ))), ) | AD38: =IF(K38<>"", IF(AND($P38=FALSE, $A38=FALSE), -K38, IF(AND($P38=FALSE, $A38=TRUE), 0, IF($P38=TRUE, (K38 / $R38) * 100 * ($S38 / 100)-K38, ))), ) | AE38: =IF(L38<>"", IF(AND($P38=FALSE, $A38=FALSE), -L38, IF(AND($P38=FALSE, $A38=TRUE), 0, IF($P38=TRUE, (L38 / $R38) * 100 * ($S38 / 100)-L38, ))), ) | AF38: =IF(M38<>"", IF(AND($P38=FALSE, $A38=FALSE), -M38, IF(AND($P38=FALSE, $A38=TRUE), 0, IF($P38=TRUE, (M38 / $R38) * 100 * ($S38 / 100)-M38, ))), ) | AG38: =IF(N38<>"", IF(AND($P38=FALSE, $A38=FALSE), -N38, IF(AND($P38=FALSE, $A38=TRUE), 0, IF($P38=TRUE, (N38 / $R38) * 100 * ($S38 / 100)-N38, ))), )
A39: FALSE | D39: 45235 | E39: NBA | F39: 🏀 23-24 11(Nov) | G39: 2 | H39: 1 | I39: 2 | P39: TRUE | R39: 5 | S39: 12.75 | T39: +155 | Z39: =IF(G39<>"", IF(AND($P39=FALSE, $A39=FALSE), -G39, IF(AND($P39=FALSE, $A39=TRUE), 0, IF($P39=TRUE, (G39 / $R39) * 100 * ($S39 / 100)-G39, ))), ) -> 3.1 | AA39: =IF(I39<>"", IF(AND($P39=FALSE, $A39=FALSE), -I39, IF(AND($P39=FALSE, $A39=TRUE), 0, IF($P39=TRUE, (I39 / $R39) * 100 * ($S39 / 100)-I39, ))), ) -> 3.1 | AB39: =IF(H39<>"", IF(AND($P39=FALSE, $A39=FALSE), -H39, IF(AND($P39=FALSE, $A39=TRUE), 0, IF($P39=TRUE, (H39 / $R39) * 100 * ($S39 / 100)-H39, ))), ) -> 1.55 | AC39: =IF(J39<>"", IF(AND($P39=FALSE, $A39=FALSE), -J39, IF(AND($P39=FALSE, $A39=TRUE), 0, IF($P39=TRUE, (J39 / $R39) * 100 * ($S39 / 100)-J39, ))), ) | AD39: =IF(K39<>"", IF(AND($P39=FALSE, $A39=FALSE), -K39, IF(AND($P39=FALSE, $A39=TRUE), 0, IF($P39=TRUE, (K39 / $R39) * 100 * ($S39 / 100)-K39, ))), ) | AE39: =IF(L39<>"", IF(AND($P39=FALSE, $A39=FALSE), -L39, IF(AND($P39=FALSE, $A39=TRUE), 0, IF($P39=TRUE, (L39 / $R39) * 100 * ($S39 / 100)-L39, ))), ) | AF39: =IF(M39<>"", IF(AND($P39=FALSE, $A39=FALSE), -M39, IF(AND($P39=FALSE, $A39=TRUE), 0, IF($P39=TRUE, (M39 / $R39) * 100 * ($S39 / 100)-M39, ))), ) | AG39: =IF(N39<>"", IF(AND($P39=FALSE, $A39=FALSE), -N39, IF(AND($P39=FALSE, $A39=TRUE), 0, IF($P39=TRUE, (N39 / $R39) * 100 * ($S39 / 100)-N39, ))), )
A40: FALSE | P40: FALSE | V40: ✅ | W40: / | X40: 20+ D. Bane p | Z40: =IF(G40<>"", IF(AND($P40=FALSE, $A40=FALSE), -G40, IF(AND($P40=FALSE, $A40=TRUE), 0, IF($P40=TRUE, (G40 / $R40) * 100 * ($S40 / 100)-G40, ))), ) | AA40: =IF(I40<>"", IF(AND($P40=FALSE, $A40=FALSE), -I40, IF(AND($P40=FALSE, $A40=TRUE), 0, IF($P40=TRUE, (I40 / $R40) * 100 * ($S40 / 100)-I40, ))), ) | AB40: =IF(H40<>"", IF(AND($P40=FALSE, $A40=FALSE), -H40, IF(AND($P40=FALSE, $A40=TRUE), 0, IF($P40=TRUE, (H40 / $R40) * 100 * ($S40 / 100)-H40, ))), ) | AC40: =IF(J40<>"", IF(AND($P40=FALSE, $A40=FALSE), -J40, IF(AND($P40=FALSE, $A40=TRUE), 0, IF($P40=TRUE, (J40 / $R40) * 100 * ($S40 / 100)-J40, ))), ) | AD40: =IF(K40<>"", IF(AND($P40=FALSE, $A40=FALSE), -K40, IF(AND($P40=FALSE, $A40=TRUE), 0, IF($P40=TRUE, (K40 / $R40) * 100 * ($S40 / 100)-K40, ))), ) | AE40: =IF(L40<>"", IF(AND($P40=FALSE, $A40=FALSE), -L40, IF(AND($P40=FALSE, $A40=TRUE), 0, IF($P40=TRUE, (L40 / $R40) * 100 * ($S40 / 100)-L40, ))), ) | AF40: =IF(M40<>"", IF(AND($P40=FALSE, $A40=FALSE), -M40, IF(AND($P40=FALSE, $A40=TRUE), 0, IF($P40=TRUE, (M40 / $R40) * 100 * ($S40 / 100)-M40, ))), ) | AG40: =IF(N40<>"", IF(AND($P40=FALSE, $A40=FALSE), -N40, IF(AND($P40=FALSE, $A40=TRUE), 0, IF($P40=TRUE, (N40 / $R40) * 100 * ($S40 / 100)-N40, ))), )
...

Sheet Por data
A1: Data | B1: Valor | C1: Motivo | E1: Data | F1: Valor | G1: Motivo | I1: Data | J1: Valor | K1: Motivo | M1: Data | N1: Valor | O1: Motivo | Q1: Data | R1: Valor | S1: Motivo | U1: Data | V1: Valor | W1: Motivo | Y1: Data | Z1: Valor | AA1: Motivo | AC1: Data | AD1: Valor | AE1: Motivo
A2: 45204 | B2: 212.49 | C2: inicio | E2: 45204 | F2: 36 | G2: inicio | I2: 45204 | J2: 313.39 | K2: inicio | M2: 45204 | N2: 248.58 | O2: inicio | Q2: 45204 | R2: 139.77 | S2: inicio | U2: 45204 | V2: 11.58 | W2: inicio | Y2: 45204 | Z2: 13.68 | AA2: inicio | AC2: 45204 | AD2: 7.78 | AE2: inicio
A3: 45251 | B3: -10 | C3: Saque | I3: 45292 | J3: -10 | K3: Jags x 9ers
A4: 45292 | B4: 10 | C4: Jags x 9ers
J6: =IF(I6<>"", SUMIF(Bets!D:D, I6, Bets!AA:AA), "")
A7: WOLF | B7: Saldo | C7: Bets +/- | E7: FELIPE | F7: Saldo | G7: Bets +/- | I7: CHOI | J7: Saldo | K7: Bets +/- | M7: JO | N7: Saldo | O7: Bets +/- | Q7: TRIGO | R7: Saldo | S7: Bets +/- | U7: HULYAN | V7: Saldo | W7: Bets +/- | Y7: BUENO | Z7: Saldo | AA7: Bets +/- | AC7: NINHO | AD7: Saldo | AE7: Bets +/-
B8: =SUM(B2:B6)+SUM(B11:B1002) -> 26.147186 | C8: =SUMIF(C11:C1002, "", B11:B1002) -> -186.34281 | F8: =SUM(F2:F6)+SUM(F11:F1002) -> -24.786815 | G8: =SUMIF(G11:G1002, "", F11:F1002) -> -60.786815 | J8: =SUM(J2:J6)+SUM(J11:J1002) -> 123.97766 | K8: =SUMIF(K11:K1002, "", J11:J1002) -> -179.41234 | N8: =SUM(N2:N6)+SUM(N11:N1002) -> 214.36947 | O8: =SUMIF(O11:O1002, "", N11:N1002) -> -34.21053 | R8: =SUM(R2:R6)+SUM(R11:R1002) -> 113.27 | S8: =SUMIF(S11:S1002, "", R11:R1002) -> -26.5 | V8: =SUM(V2:V6)+SUM(V11:V1002) -> 0.5825 | W8: =SUMIF(W11:W1002, "", V11:V1002) -> -10.9975 | Z8: =SUM(Z2:Z6)+SUM(Z11:Z1002) -> 13.68 | AA8: =SUMIF(AA11:AA1002, "", Z11:Z1002) -> 0 | AD8: =SUM(AD2:AD6)+SUM(AD11:AD1002) -> 7.78 | AE8: =SUMIF(AE11:AE1002, "", AD11:AD1002) -> 0
A9: . | B9: . | C9: . | D9: . | E9: . | F9: . | G9: . | I9: . | J9: . | K9: . | L9: . | M9: . | N9: . | O9: . | P9: . | Q9: . | R9: . | S9: . | T9: . | U9: . | V9: . | W9: . | X9: . | Y9: . | Z9: . | AA9: . | AB9: . | AC9: . | AD9: . | AE9: .
A10: Data | B10: Valor | E10: Data | F10: Valor | I10: Data | J10: Valor | M10: Data | N10: Valor | Q10: Data | R10: Valor | U10: Data | V10: Valor | Y10: Data | Z10: Valor | AC10: Data | AD10: Valor
A11: =IFERROR(__xludf.DUMMYFUNCTION("SORT(UNIQUE(FILTER(Bets!$D$2:$D1002, Bets!$D$2:$D1002<>"""", Bets!Z2:Z1002<>"""")),1, FALSE)"),46184.0) -> 46184 | B11: =IF(A11<>"", SUMIF(Bets!$D:$D, A11, Bets!Z:Z), "") -> 1.92 | E11: =IFERROR(__xludf.DUMMYFUNCTION("SORT(UNIQUE(FILTER(Bets!$D$2:$D1002, Bets!$D$2:$D1002<>"""", Bets!AB2:AB1002<>"""")),1, FALSE)"),46061.0) -> 46061 | F11: =IF(E11<>"", SUMIF(Bets!$D:$D, E11, Bets!AB:AB), "") -> -3 | I11: =IFERROR(__xludf.DUMMYFUNCTION("SORT(UNIQUE(FILTER(Bets!$D$2:$D1002, Bets!$D$2:$D1002<>"""", Bets!AA2:AA1002<>"""")),1, FALSE)"),46184.0) -> 46184 | J11: =IF(I11<>"", SUMIF(Bets!$D:$D, I11, Bets!AA:AA), "") -> 2.88 | M11: =IFERROR(__xludf.DUMMYFUNCTION("SORT(UNIQUE(FILTER(Bets!$D$2:$D1002, Bets!$D$2:$D1002<>"""", Bets!AC2:AC1002<>"""")),1, FALSE)"),46061.0) -> 46061 | N11: =IF(M11<>"", SUMIF(Bets!$D:$D, M11, Bets!AC:AC), "") -> -5 | Q11: =IFERROR(__xludf.DUMMYFUNCTION("IFERROR(UNIQUE(FILTER(Bets!$D$2:$D1002, Bets!$D$2:$D1002<>"""", Bets!AD2:AD1002<>"""")),)"),45333.0) -> 45333 | R11: =IF(Q11<>"", SUMIF(Bets!$D:$D, Q11, Bets!AD:AD), "") -> -10 | U11: =IFERROR(__xludf.DUMMYFUNCTION("IFERROR(UNIQUE(FILTER(Bets!$D$2:$D1002, Bets!$D$2:$D1002<>"""", Bets!AE2:AE1002<>"""")),)"),45266.0) -> 45266 | V11: =IF(U11<>"", SUMIF(Bets!$D:$D, U11, Bets!AE:AE), "") -> -6 | Y11: =IFERROR(__xludf.DUMMYFUNCTION("IFERROR(UNIQUE(FILTER(Bets!$D$2:$D1002, Bets!$D$2:$D1002<>"""", Bets!AF2:AF1002<>"""")),)"),"") | Z11: =IF(Y11<>"", SUMIF(Bets!$D:$D, Y11, Bets!AF:AF), "") | AC11: =IFERROR(__xludf.DUMMYFUNCTION("IFERROR(UNIQUE(FILTER(Bets!$D$2:$D1002, Bets!$D$2:$D1002<>"""", Bets!AG2:AG1002<>"""")),)"),"") | AD11: =IF(AC11<>"", SUMIF(Bets!$D:$D, AC11, Bets!AG:AG), "")
A12: =IFERROR(__xludf.DUMMYFUNCTION("""COMPUTED_VALUE"""),46061.0) -> 46061 | B12: =IF(A12<>"", SUMIF(Bets!$D:$D, A12, Bets!Z:Z), "") -> -19.5 | E12: =IFERROR(__xludf.DUMMYFUNCTION("""COMPUTED_VALUE"""),45977.0) -> 45977 | F12: =IF(E12<>"", SUMIF(Bets!$D:$D, E12, Bets!AB:AB), "") -> -3 | I12: =IFERROR(__xludf.DUMMYFUNCTION("""COMPUTED_VALUE"""),46061.0) -> 46061 | J12: =IF(I12<>"", SUMIF(Bets!$D:$D, I12, Bets!AA:AA), "") -> -44 | M12: =IFERROR(__xludf.DUMMYFUNCTION("""COMPUTED_VALUE"""),45541.0) -> 45541 | N12: =IF(M12<>"", SUMIF(Bets!$D:$D, M12, Bets!AC:AC), "") -> 4.1533333 | Q12: =IFERROR(__xludf.DUMMYFUNCTION("""COMPUTED_VALUE"""),45904.0) -> 45904 | R12: =IF(Q12<>"", SUMIF(Bets!$D:$D, Q12, Bets!AD:AD), "") -> -2 | U12: =IFERROR(__xludf.DUMMYFUNCTION("""COMPUTED_VALUE"""),45333.0) -> 45333 | V12: =IF(U12<>"", SUMIF(Bets!$D:$D, U12, Bets!AE:AE), "") -> -3.3375 | Z12: =IF(Y12<>"", SUMIF(Bets!$D:$D, Y12, Bets!AF:AF), "") | AD12: =IF(AC12<>"", SUMIF(Bets!$D:$D, AC12, Bets!AG:AG), "")
A13: =IFERROR(__xludf.DUMMYFUNCTION("""COMPUTED_VALUE"""),46025.0) -> 46025 | B13: =IF(A13<>"", SUMIF(Bets!$D:$D, A13, Bets!Z:Z), "") -> -12 | E13: =IFERROR(__xludf.DUMMYFUNCTION("""COMPUTED_VALUE"""),45963.0) -> 45963 | F13: =IF(E13<>"", SUMIF(Bets!$D:$D, E13, Bets!AB:AB), "") -> -8.5 | I13: =IFERROR(__xludf.DUMMYFUNCTION("""COMPUTED_VALUE"""),46025.0) -> 46025 | J13: =IF(I13<>"", SUMIF(Bets!$D:$D, I13, Bets!AA:AA), "") -> -14 | M13: =IFERROR(__xludf.DUMMYFUNCTION("""COMPUTED_VALUE"""),45540.0) -> 45540 | N13: =IF(M13<>"", SUMIF(Bets!$D:$D, M13, Bets!AC:AC), "") -> -2.28 | Q13: =IFERROR(__xludf.DUMMYFUNCTION("""COMPUTED_VALUE"""),45941.0) -> 45941 | R13: =IF(Q13<>"", SUMIF(Bets!$D:$D, Q13, Bets!AD:AD), "") -> -3 | U13: =IFERROR(__xludf.DUMMYFUNCTION("""COMPUTED_VALUE"""),45908.0) -> 45908 | V13: =IF(U13<>"", SUMIF(Bets!$D:$D, U13, Bets!AE:AE), "") -> -1.66 | Z13: =IF(Y13<>"", SUMIF(Bets!$D:$D, Y13, Bets!AF:AF), "") | AD13: =IF(AC13<>"", SUMIF(Bets!$D:$D, AC13, Bets!AG:AG), "")
A14: =IFERROR(__xludf.DUMMYFUNCTION("""COMPUTED_VALUE"""),46019.0) -> 46019 | B14: =IF(A14<>"", SUMIF(Bets!$D:$D, A14, Bets!Z:Z), "") -> 11.938 | E14: =IFERROR(__xludf.DUMMYFUNCTION("""COMPUTED_VALUE"""),45333.0) -> 45333 | F14: =IF(E14<>"", SUMIF(Bets!$D:$D, E14, Bets!AB:AB), "") -> -1 | I14: =IFERROR(__xludf.DUMMYFUNCTION("""COMPUTED_VALUE"""),46019.0) -> 46019 | J14: =IF(I14<>"", SUMIF(Bets!$D:$D, I14, Bets!AA:AA), "") -> 10.772 | M14: =IFERROR(__xludf.DUMMYFUNCTION("""COMPUTED_VALUE"""),45333.0) -> 45333 | N14: =IF(M14<>"", SUMIF(Bets!$D:$D, M14, Bets!AC:AC), "") -> -3.0838636 | Q14: =IFERROR(__xludf.DUMMYFUNCTION("""COMPUTED_VALUE"""),46061.0) -> 46061 | R14: =IF(Q14<>"", SUMIF(Bets!$D:$D, Q14, Bets!AD:AD), "") -> -11.5 | V14: =IF(U14<>"", SUMIF(Bets!$D:$D, U14, Bets!AE:AE), "") | Z14: =IF(Y14<>"", SUMIF(Bets!$D:$D, Y14, Bets!AF:AF), "") | AD14: =IF(AC14<>"", SUMIF(Bets!$D:$D, AC14, Bets!AG:AG), "")
A15: =IFERROR(__xludf.DUMMYFUNCTION("""COMPUTED_VALUE"""),46012.0) -> 46012 | B15: =IF(A15<>"", SUMIF(Bets!$D:$D, A15, Bets!Z:Z), "") -> -0.352 | E15: =IFERROR(__xludf.DUMMYFUNCTION("""COMPUTED_VALUE"""),45322.0) -> 45322 | F15: =IF(E15<>"", SUMIF(Bets!$D:$D, E15, Bets!AB:AB), "") -> -2 | I15: =IFERROR(__xludf.DUMMYFUNCTION("""COMPUTED_VALUE"""),46012.0) -> 46012 | J15: =IF(I15<>"", SUMIF(Bets!$D:$D, I15, Bets!AA:AA), "") -> -1.028 | M15: =IFERROR(__xludf.DUMMYFUNCTION("""COMPUTED_VALUE"""),45269.0) -> 45269 | N15: =IF(M15<>"", SUMIF(Bets!$D:$D, M15, Bets!AC:AC), "") -> -7.5 | R15: =IF(Q15<>"", SUMIF(Bets!$D:$D, Q15, Bets!AD:AD), "") | V15: =IF(U15<>"", SUMIF(Bets!$D:$D, U15, Bets!AE:AE), "") | Z15: =IF(Y15<>"", SUMIF(Bets!$D:$D, Y15, Bets!AF:AF), "") | AD15: =IF(AC15<>"", SUMIF(Bets!$D:$D, AC15, Bets!AG:AG), "")
A16: =IFERROR(__xludf.DUMMYFUNCTION("""COMPUTED_VALUE"""),46009.0) -> 46009 | B16: =IF(A16<>"", SUMIF(Bets!$D:$D, A16, Bets!Z:Z), "") -> 9.93 | E16: =IFERROR(__xludf.DUMMYFUNCTION("""COMPUTED_VALUE"""),45319.0) -> 45319 | F16: =IF(E16<>"", SUMIF(Bets!$D:$D, E16, Bets!AB:AB), "") -> 2.794 | I16: =IFERROR(__xludf.DUMMYFUNCTION("""COMPUTED_VALUE"""),46009.0) -> 46009 | J16: =IF(I16<>"", SUMIF(Bets!$D:$D, I16, Bets!AA:AA), "") -> 19.86 | M16: =IFERROR(__xludf.DUMMYFUNCTION("""COMPUTED_VALUE"""),45264.0) -> 45264 | N16: =IF(M16<>"", SUMIF(Bets!$D:$D, M16, Bets!AC:AC), "") -> -3 | R16: =IF(Q16<>"", SUMIF(Bets!$D:$D, Q16, Bets!AD:AD), "") | V16: =IF(U16<>"", SUMIF(Bets!$D:$D, U16, Bets!AE:AE), "") | Z16: =IF(Y16<>"", SUMIF(Bets!$D:$D, Y16, Bets!AF:AF), "") | AD16: =IF(AC16<>"", SUMIF(Bets!$D:$D, AC16, Bets!AG:AG), "")
A17: =IFERROR(__xludf.DUMMYFUNCTION("""COMPUTED_VALUE"""),45984.0) -> 45984 | B17: =IF(A17<>"", SUMIF(Bets!$D:$D, A17, Bets!Z:Z), "") -> -9.0977143 | E17: =IFERROR(__xludf.DUMMYFUNCTION("""COMPUTED_VALUE"""),45317.0) -> 45317 | F17: =IF(E17<>"", SUMIF(Bets!$D:$D, E17, Bets!AB:AB), "") -> -1 | I17: =IFERROR(__xludf.DUMMYFUNCTION("""COMPUTED_VALUE"""),45984.0) -> 45984 | J17: =IF(I17<>"", SUMIF(Bets!$D:$D, I17, Bets!AA:AA), "") -> 1.6077143 | M17: =IFERROR(__xludf.DUMMYFUNCTION("""COMPUTED_VALUE"""),45263.0) -> 45263 | N17: =IF(M17<>"", SUMIF(Bets!$D:$D, M17, Bets!AC:AC), "") -> -2.5 | R17: =IF(Q17<>"", SUMIF(Bets!$D:$D, Q17, Bets!AD:AD), "") | V17: =IF(U17<>"", SUMIF(Bets!$D:$D, U17, Bets!AE:AE), "") | Z17: =IF(Y17<>"", SUMIF(Bets!$D:$D, Y17, Bets!AF:AF), "") | AD17: =IF(AC17<>"", SUMIF(Bets!$D:$D, AC17, Bets!AG:AG), "")
